Workbook

Sheet 12월
A1: 45992
A2: 월요일 | B2: 화요일 | C2: 수요일 | D2: 목요일 | E2: 금요일 | F2: 토요일
A3: 1 | B3: 2 | C3: 3 | D3: 4 | E3: 5 | F3: 6 | G3: 진로개발 | H3: =COUNTIF($A:$F, "*진로개발*") -> 15 | I3: 강 진 | J3: =COUNTIF($A:$F, "*강 진*") -> 4
A4: 10:00 이공계(정지선) | B4: 10:00 진로개발(신민이) | C4: 10:00 서류면접 (한 나) | D4: 10:00 공기업 (김선화) | E4: 10:30 서류면접 (이희영) | G4: 서류면접 | H4: =COUNTIF($A:$F, "*서류면접*") -> 38 | I4: 김나영 | J4: =COUNTIF($A:$F, "*김나영*") -> 4
A5: 11:00 이공계(정지선) | B5: 11:00 진로개발(신민이) | C5: 11:00 서류면접 (한 나) | D5: 11:00 서류면접 (김선화) | E5: 11:30 서류면접 (이희영) | G5: 공기업 | H5: =COUNTIF($A:$F, "*공기업*") -> 4 | I5: 김미령 | J5: =COUNTIF($A:$F, "*김미령*") -> 0
G6: 외국계 | H6: =COUNTIF($A:$F, "*외국계*") -> 5 | I6: 김민경 | J6: =COUNTIF($A:$F, "*김민경*") -> 5
C7: 10:30 서류면접(김지현) | G7: 이공계 | H7: =COUNTIF($A:$F, "*이공계*") -> 2 | I7: 김선화 | J7: =COUNTIF($A:$F, "*김선화*") -> 4
C8: 11:30 서류면접(김지현) | D8: 10:00 공기업 (심영섭) | G8: 콘텐츠 | H8: =COUNTIF($A:$F, "*콘텐츠*") -> 0 | I8: 김세희 | J8: =COUNTIF($A:$F, "*김세희*") -> 0
D9: 11:00 서류면접 (심영섭) | E9: 10:00 서류면접(장신혜) | G9: 금융 | H9: =COUNTIF($A:$F, "*금융*") -> 0 | I9: 김지현 | J9: =COUNTIF($A:$F, "*김지현*") -> 5
C10: 11:00 진로개발 (범하나) | E10: 11:00 서류면접(장신혜) | G10: IT | H10: =COUNTIF($A:$F, "*IT*") -> 0 | I10: 범하나 | J10: =COUNTIF($A:$F, "*범하나*") -> 4
C11: 12:00 진로개발 (범하나) | G11: 임원면접 | H11: =COUNTIF($A:$F, "*임원면접*") -> 0 | I11: 성지우 | J11: =COUNTIF($A:$F, "*성지우*") -> 3
B12: 10:30 서류면접 (김민경) | D12: 11:00 진로개발(김나영) | G12: TOTAL | H12: =sum(H3:H11) -> 64 | I12: 신민이 | J12: =COUNTIF($A:$F, "*신민이*") -> 6
B13: 11:30 서류면접 (김민경) | D13: 12:00 진로개발(김나영) | E13: 16:00 외국계(성지우) | I13: 심영섭 | J13: =COUNTIF($A:$F, "*심영섭*") -> 7
B14: 12:30 서류면접 (김민경) | E14: 17:00 외국계(성지우) | I14: 양우석 | J14: =COUNTIF($A:$F, "*양우석*") -> 0
I15: 이상환 | J15: =COUNTIF($A:$F, "*이상환*") -> 0
A16: 13:00 서류면접(강 진) | I16: 이주환 | J16: =COUNTIF($A:$F, "*이주환*") -> 0
A17: 14:00 서류면접(강 진) | I17: 이하영 | J17: =COUNTIF($A:$F, "*이하영*") -> 0
I18: 이효숙 | J18: =COUNTIF($A:$F, "*이효숙*") -> 0
I19: 이희영 | J19: =COUNTIF($A:$F, "*이희영*") -> 6
I20: 장신혜 | J20: =COUNTIF($A:$F, "*장신혜*") -> 6
I21: 정지선 | J21: =COUNTIF($A:$F, "*정지선*") -> 4
I22: 지명선 | J22: =COUNTIF($A:$F, "*지명선*") -> 2
A23: 8 | B23: 9 | C23: 10 | D23: 11 | E23: 12 | F23: 13 | I23: 최은주 | J23: =COUNTIF($A:$F, "*최은주*") -> 0
A24: 기말고사 | I24: 한 나 | J24: =COUNTIF($A:$F, "*한 나*") -> 4
I25: 민현정 | J25: =COUNTIF($A:$F, "*민현정*") -> 0
B26: 10:00 서류면접 (심영섭) | I26: TOTAL | J26: =sum(J3:J25) -> 64
B27: 11:00 서류면접 (심영섭)
B28: 12:00 서류면접 (심영섭) | C28: 10:30 서류면접(김지현)
C29: 11:30 서류면접(김지현)
C30: 12:30 서류면접(김지현)
A44: 15 | B44: 16 | C44: 17 | D44: 18 | E44: 19 | F44: 20
A45: 기말고사
B46: 10:00 진로개발(신민이) | C46: 10:00 서류면접 (한 나) | D46: 10:00 공기업 (김선화) | E46: 10:30 서류면접 (이희영)
B47: 11:00 진로개발(신민이) | C47: 11:00 서류면접 (한 나) | D47: 11:00 서류면접 (김선화) | E47: 11:30 서류면접 (이희영)
E51: 10:00 서류면접(장신혜)
C52: 11:00 진로개발 (범하나) | D52: 11:00 서류면접(김나영) | E52: 11:00 서류면접(장신혜)
C53: 12:00 진로개발 (범하나) | D53: 12:00 진로개발(김나영)
E56: 10:00 공기업 (심영섭)
E57: 11:00 서류면접 (심영섭)
A66: 22 | B66: 23 | C66: 24 | D66: 25 | E66: 26 | F66: 27
...

Sheet 11월
A1: 45962
A2: 월요일 | B2: 화요일 | C2: 수요일 | D2: 목요일 | E2: 금요일 | F2: 토요일
F3: 1 | G3: 진로개발 | H3: =COUNTIF($A:$F, "*진로개발*") -> 19 | I3: 강 진 | J3: =COUNTIF($A:$F, "*강 진*") -> 11
F4: 1 DAY 모의면접 | G4: 서류면접 | H4: =COUNTIF($A:$F, "*서류면접*") -> 110 | I4: 김나영 | J4: =COUNTIF($A:$F, "*김나영*") -> 9
G5: 공기업 | H5: =COUNTIF($A:$F, "*공기업*") -> 6 | I5: 김미령 | J5: =COUNTIF($A:$F, "*김미령*") -> 0
F6: 10:00 이공계(김세희) | G6: 외국계 | H6: =COUNTIF($A:$F, "*외국계*") -> 7 | I6: 김민경 | J6: =COUNTIF($A:$F, "*김민경*") -> 11
F7: 11:00 이공계(김세희) | G7: 이공계 | H7: =COUNTIF($A:$F, "*이공계*") -> 20 | I7: 김선화 | J7: =COUNTIF($A:$F, "*김선화*") -> 8
F8: 12:00 이공계(김세희) | G8: 콘텐츠 | H8: =COUNTIF($A:$F, "*콘텐츠*") -> 6 | I8: 김세희 | J8: =COUNTIF($A:$F, "*김세희*") -> 9
G9: 금융 | H9: =COUNTIF($A:$F, "*금융*") -> 0 | I9: 김지현 | J9: =COUNTIF($A:$F, "*김지현*") -> 11
G10: IT | H10: =COUNTIF($A:$F, "*IT*") -> 0 | I10: 범하나 | J10: =COUNTIF($A:$F, "*범하나*") -> 11
G11: 임원면접 | H11: =COUNTIF($A:$F, "*임원면접*") -> 9 | I11: 성지우 | J11: =COUNTIF($A:$F, "*성지우*") -> 5
G12: TOTAL | H12: =sum(H3:H11) -> 177 | I12: 신민이 | J12: =COUNTIF($A:$F, "*신민이*") -> 10
I13: 심영섭 | J13: =COUNTIF($A:$F, "*심영섭*") -> 21
I14: 양우석 | J14: =COUNTIF($A:$F, "*양우석*") -> 9
I15: 이상환 | J15: =COUNTIF($A:$F, "*이상환*") -> 6
I16: 이주환 | J16: =COUNTIF($A:$F, "*이주환*") -> 0
I17: 이하영 | J17: =COUNTIF($A:$F, "*이하영*") -> 0
I18: 이효숙 | J18: =COUNTIF($A:$F, "*이효숙*") -> 0
I19: 이희영 | J19: =COUNTIF($A:$F, "*이희영*") -> 21
A20: 3 | B20: 4 | C20: 5 | D20: 6 | E20: 7 | F20: 8 | I20: 장신혜 | J20: =COUNTIF($A:$F, "*장신혜*") -> 11
A21: 10:00 이공계(정지선_대면)* | C21: 10:00 서류면접 (한 나) | D21: 10:00 공기업 (김선화) | E21: 10:30 서류면접 (이희영) | I21: 정지선 | J21: =COUNTIF($A:$F, "*정지선*") -> 14
A22: 11:00 이공계(정지선_대면)* | C22: 11:00 서류면접 (한 나) | D22: 11:00 서류면접 (김선화) | E22: 11:30 서류면접 (이희영) | I22: 지명선 | J22: =COUNTIF($A:$F, "*지명선*") -> 2
A23: 12:00 이공계(정지선_대면)* | E23: 12:30 서류면접 (이희영) | I23: 최은주 | J23: =COUNTIF($A:$F, "*최은주*") -> 0
E24: 13:30 서류면접 (이희영)
D25: 10:30 콘텐츠엔터(이상환) | F25: 9:30 서류면접(심영섭) | I25: 한 나 | J25: =COUNTIF($A:$F, "*한 나*") -> 8
B26: 10:00 공기업 (심영섭_대면)* | D26: 11:30 콘텐츠엔터(이상환) | F26: 10:30 서류면접 (심영섭) | I26: 민현정 | J26: =COUNTIF($A:$F, "*민현정*") -> 0
B27: 11:00 서류면접 (심영섭_대면)* | E27: 10:00 서류면접(장신혜) | F27: 11:30 서류면접 (심영섭) | I27: TOTAL | J27: =sum(J3:J26) -> 177
A28: 10:30 서류면접(김지현_대면)* | B28: 12:00 서류면접 (심영섭_대면)* | C28: 11:00 서류면접 (범하나_대면)* | D28: 11:00 진로개발(김나영) | E28: 11:00 서류면접(장신혜)
A29: 11:30 서류면접(김지현_대면)* | C29: 12:00 서류면접 (범하나_대면)* | D29: 12:00 진로개발(김나영) | E29: 12:00 서류면접(장신혜) | F29: 10:30 서류면접 (이희영)
A30: 12:30 서류면접(김지현_대면)* | C30: 13:00 서류면접 (범하나_대면)* | D30: 13:00 진로개발(김나영) | F30: 11:30 서류면접 (이희영)
B31: 11:30 서류면접 (김민경) | F31: 12:30 서류면접 (이희영)
B32: 12:30 서류면접 (김민경) | D32: 09:00 진로개발(신민이) | E32: 10:10 서류면접(강 진_대면)*
B33: 13:30 서류면접 (김민경) | D33: 10:00 진로개발(신민이) | E33: 11:10 서류면접 (강 진_대면)* | F33: 10:00 서류면접(정지선)
E34: 12:10 서류면접 (강 진_대면)* | F34: 11:00 서류면접(정지선)
F35: 12:00 서류면접(정지선)
B36: 14:00 임원면접 (양우석) | C36: 14:00 임원면접 (양우석) | D36: 14:00 임원면접 (양우석) | E36: 13:00 진로개발(신민이)
D38: 15:00 외국계(성지우)
D39: 16:00 외국계(성지우)
A41: 10 | B41: 11 | C41: 12 | D41: 13 | E41: 14 | F41: 15
A42: 10:00 이공계(정지선_대면)* | B42: 10:00 진로개발(신민이) | C42: 10:00 서류면접 (한 나) | D42: 10:00 공기업 (김선화) | E42: 10:30 서류면접 (이희영)
...

Sheet 10월
A1: 45931
A2: 월요일 | B2: 화요일 | C2: 수요일 | D2: 목요일 | E2: 금요일 | F2: 토요일
C3: 1 | D3: 2 | E3: 3 | F3: 4 | G3: 진로개발 | H3: =COUNTIF($A:$F, "*진로개발*") -> 15 | I3: 강 진 | J3: =COUNTIF($A:$F, "*강 진*") -> 3
C4: 10:00 서류면접 (한 나) | D4: 10:00 서류면접 (김선화) | E4: 개천절 | G4: 서류면접 | H4: =COUNTIF($A:$F, "*서류면접*") -> 51 | I4: 김나영 | J4: =COUNTIF($A:$F, "*김나영*") -> 8
C5: 11:00 서류면접 (한 나) | D5: 11:00 서류면접 (김선화) | G5: 공기업 | H5: =COUNTIF($A:$F, "*공기업*") -> 3 | I5: 김미령 | J5: =COUNTIF($A:$F, "*김미령*") -> 0
G6: 외국계 | H6: =COUNTIF($A:$F, "*외국계*") -> 4 | I6: 김민경 | J6: =COUNTIF($A:$F, "*김민경*") -> 3
G7: 이공계 | H7: =COUNTIF($A:$F, "*이공계*") -> 3 | I7: 김선화 | J7: =COUNTIF($A:$F, "*김선화*") -> 6
D8: 10:30 서류면접 (이상환) | G8: 콘텐츠 | H8: =COUNTIF($A:$F, "*콘텐츠*") -> 5 | I8: 김세희 | J8: =COUNTIF($A:$F, "*김세희*") -> 2
D9: 11:30 콘텐츠엔터(이상환) | G9: 금융 | H9: =COUNTIF($A:$F, "*금융*") -> 0 | I9: 김지현 | J9: =COUNTIF($A:$F, "*김지현*") -> 5
C10: 11:00 서류면접 (범하나_대면)* | G10: IT | H10: =COUNTIF($A:$F, "*IT*") -> 0 | I10: 범하나 | J10: =COUNTIF($A:$F, "*범하나*") -> 9
C11: 12:00 서류면접 (범하나_대면)* | G11: 임원면접 | H11: =COUNTIF($A:$F, "*임원면접*") -> 0 | I11: 성지우 | J11: =COUNTIF($A:$F, "*성지우*") -> 2
C12: 13:00 서류면접 (범하나_대면)* | D12: 11:00 진로개발(김나영) | G12: TOTAL | H12: =sum(H3:H11) -> 81 | I12: 신민이 | J12: =COUNTIF($A:$F, "*신민이*") -> 3
D13: 12:00 진로개발(김나영) | I13: 심영섭 | J13: =COUNTIF($A:$F, "*심영섭*") -> 3
D14: 13:00 진로개발(김나영) | I14: 양우석 | J14: =COUNTIF($A:$F, "*양우석*") -> 0
I15: 이상환 | J15: =COUNTIF($A:$F, "*이상환*") -> 6
I16: 이주환 | J16: =COUNTIF($A:$F, "*이주환*") -> 0
I17: 이하영 | J17: =COUNTIF($A:$F, "*이하영*") -> 0
I18: 이효숙 | J18: =COUNTIF($A:$F, "*이효숙*") -> 0
I19: 이희영 | J19: =COUNTIF($A:$F, "*이희영*") -> 11
I20: 장신혜 | J20: =COUNTIF($A:$F, "*장신혜*") -> 11
I21: 정지선 | J21: =COUNTIF($A:$F, "*정지선*") -> 1
A22: 6 | B22: 7 | C22: 8 | D22: 9 | E22: 10 | F22: 11 | I22: 지명선 | J22: =COUNTIF($A:$F, "*지명선*") -> 2
A23: 추석연휴 | D23: 한글날 | E23: 10:30 서류면접 (이희영) | F23: 10:00 이공계(김세희) | I23: 최은주 | J23: =COUNTIF($A:$F, "*최은주*") -> 0
E24: 11:30 서류면접 (이희영) | F24: 11:00 이공계(김세희) | I24: 한 나 | J24: =COUNTIF($A:$F, "*한 나*") -> 6
E25: 12:30 서류면접 (이희영) | I25: 민현정 | J25: =COUNTIF($A:$F, "*민현정*") -> 0
F26: 10:30 서류면접 (이희영) | I26: TOTAL | J26: =sum(J3:J25) -> 81
F27: 11:30 서류면접 (이희영)
E28: 10:00 서류면접(장신혜) | F28: 12:30 서류면접 (이희영)
E29: 11:00 서류면접(장신혜)
E30: 12:00 서류면접(장신혜)
E32: 10:30 외국계(지명선)
E33: 11:30 외국계(지명선)
A41: 13 | B41: 14 | C41: 15 | D41: 16 | E41: 17 | F41: 18
B42: 10:00 진로개발(신민이) | C42: 10:00 서류면접 (한 나) | E42: 10:30 서류면접 (이희영)
B43: 11:00 진로개발(신민이) | C43: 11:00 서류면접 (한 나) | E43: 11:30 서류면접 (이희영)
A44: 12:00 이공계(정지선_대면)* | B44: 12:00 진로개발(신민이)
D46: 10:30 콘텐츠엔터(이상환)
B47: 10:00 공기업 (심영섭_대면)* | D47: 11:30 콘텐츠엔터(이상환) | E47: 10:00 서류면접(장신혜)
B48: 11:00 서류면접 (심영섭_대면)* | C48: 11:00 진로개발 (범하나_대면)*
B49: 12:00 서류면접 (심영섭_대면)* | C49: 12:00 서류면접 (범하나_대면)* | E49: 12:00 서류면접(장신혜)
...

Sheet 9월
A1: 45901
A2: 월요일 | B2: 화요일 | C2: 수요일 | D2: 목요일 | E2: 금요일 | F2: 토요일
A3: 1 | B3: 2 | C3: 3 | D3: 4 | E3: 5 | F3: 6 | G3: 진로개발 | H3: =COUNTIF($A:$F, "*진로개발*") -> 22 | I3: 강 진 | J3: =COUNTIF($A:$F, "*강 진*") -> 10
A4: 10:00 이공계(정지선) | B4: 10:00 서류면접(신민이) | C4: 삼성 서류마감 | D4: JOBFAIR | E4: JOBFAIR | F4: 10:00 이공계(김세희) | G4: 서류면접 | H4: =COUNTIF($A:$F, "*서류면접*") -> 130 | I4: 김나영 | J4: =COUNTIF($A:$F, "*김나영*") -> 12
A5: 11:00 이공계(정지선) | B5: 11:00 서류면접(신민이) | D5: 10:00 공기업 (김선화) | E5: 10:30 서류면접 (이희영) | F5: 11:00 이공계(김세희) | G5: 공기업 | H5: =COUNTIF($A:$F, "*공기업*") -> 6 | I5: 김미령 | J5: =COUNTIF($A:$F, "*김미령*") -> 0
A6: 12:00 이공계(정지선) | B6: 12:00 서류면접(신민이) | C6: 10:00 서류면접 (한 나) | D6: 11:00 서류면접 (김선화) | E6: 11:30 서류면접 (이희영) | F6: 12:00 이공계(김세희) | G6: 외국계 | H6: =COUNTIF($A:$F, "*외국계*") -> 8 | I6: 김민경 | J6: =COUNTIF($A:$F, "*김민경*") -> 8
C7: 11:00 서류면접 (한 나) | E7: 12:30 서류면접 (이희영) | G7: 이공계 | H7: =COUNTIF($A:$F, "*이공계*") -> 20 | I7: 김선화 | J7: =COUNTIF($A:$F, "*김선화*") -> 8
B8: 10:00 공기업 (심영섭_대면)* | C8: 12:00 서류면접 (한 나) | G8: 콘텐츠 | H8: =COUNTIF($A:$F, "*콘텐츠*") -> 6 | I8: 김세희 | J8: =COUNTIF($A:$F, "*김세희*") -> 8
A9: 10:30 서류면접(김지현_대면)* | B9: 11:00 서류면접 (심영섭_대면)* | D9: 10:30 콘텐츠엔터(이상환) | F9: 9:30 서류면접(심영섭) | G9: 금융 | H9: =COUNTIF($A:$F, "*금융*") -> 0 | I9: 김지현 | J9: =COUNTIF($A:$F, "*김지현*") -> 14
B10: 12:00 서류면접 (심영섭_대면)* | C10: 11:00 서류면접 (범하나_대면)* | D10: 11:30 콘텐츠엔터(이상환) | E10: 10:00 서류면접(장신혜) | F10: 10:30 서류면접 (심영섭) | G10: IT | H10: =COUNTIF($A:$F, "*IT*") -> 0 | I10: 범하나 | J10: =COUNTIF($A:$F, "*범하나*") -> 14
A11: 12:30 서류면접(김지현_대면)* | B11: 점심 | C11: 12:00 서류면접 (범하나_대면)* | E11: 11:00 서류면접(장신혜) | F11: 11:30 서류면접 (심영섭) | G11: 임원면접 | H11: =COUNTIF($A:$F, "*임원면접*") -> 0 | I11: 성지우 | J11: =COUNTIF($A:$F, "*성지우*") -> 4
A12: 점심 | B12: 14:00 서류면접 (심영섭_대면)* | C12: 13:00 서류면접 (범하나_대면)* | E12: 12:00 서류면접(장신혜) | G12: TOTAL | H12: =sum(H3:H11) -> 192 | I12: 신민이 | J12: =COUNTIF($A:$F, "*신민이*") -> 15
A13: 14:00 서류면접(김지현_대면)* | B13: 15:00 서류면접 (심영섭_대면)* | C13: 14:00 서류면접 (범하나_대면)* | D13: 11:00 진로개발(김나영) | F13: 10:30 서류면접 (이희영) | I13: 심영섭 | J13: =COUNTIF($A:$F, "*심영섭*") -> 30
A14: 15:00 서류면접(김지현_대면)* | B14: 16:00 서류면접 (심영섭_대면)* | D14: 12:00 진로개발(김나영) | F14: 11:30 서류면접 (이희영) | I14: 양우석 | J14: =COUNTIF($A:$F, "*양우석*") -> 0
A15: 16:00 서류면접(김지현) | D15: 13:00 진로개발(김나영) | F15: 12:30 서류면접 (이희영) | I15: 이상환 | J15: =COUNTIF($A:$F, "*이상환*") -> 8
C16: 15:00 외국계(성지우) | I16: 이주환 | J16: =COUNTIF($A:$F, "*이주환*") -> 0
A17: 13:00 서류면접(강 진_대면)* | B17: 11:30 서류면접 (이희영) | C17: 16:00 외국계(성지우) | I17: 이하영 | J17: =COUNTIF($A:$F, "*이하영*") -> 0
A18: 14:00 서류면접 (강 진) | B18: 12:30 서류면접 (이희영) | I18: 이효숙 | J18: =COUNTIF($A:$F, "*이효숙*") -> 0
A19: 15:00 서류면접 (강 진_대면)* | B19: 13:30 서류면접 (이희영) | I19: 이희영 | J19: =COUNTIF($A:$F, "*이희영*") -> 24
A20: 16:00 서류면접 (강 진) | I20: 장신혜 | J20: =COUNTIF($A:$F, "*장신혜*") -> 9
I21: 정지선 | J21: =COUNTIF($A:$F, "*정지선*") -> 14
A22: 8 | B22: 9 | C22: 10 | D22: 11 | E22: 12 | F22: 13 | I22: 지명선 | J22: =COUNTIF($A:$F, "*지명선*") -> 4
A23: 10:00 이공계(정지선_대면)* | B23: 10:00 서류면접(신민이) | C23: 10:00 서류면접 (한 나) | D23: 17:00 공기업 (김선화) | E23: 10:30 서류면접 (이희영) | F23: 10:00 이공계(김세희) | I23: 최은주 | J23: =COUNTIF($A:$F, "*최은주*") -> 0
B24: 11:00 서류면접(신민이) | C24: 11:00 서류면접 (한 나) | E24: 11:30 서류면접 (이희영) | F24: 11:00 이공계(김세희) | I24: 한 나 | J24: =COUNTIF($A:$F, "*한 나*") -> 10
A25: 12:00 이공계(정지선_대면)* | B25: 12:00서류면접(신민이) | C25: 12:00 서류면접 (한 나) | E25: 12:30 서류면접 (이희영) | F25: 12:00 서류면접(김세희) | I25: 민현정 | J25: =COUNTIF($A:$F, "*민현정*") -> 0
I26: TOTAL | J26: =sum(J3:J25) -> 192
B27: 10:00 공기업 (심영섭_대면)* | F27: 9:30 서류면접(심영섭)
B28: 11:00 서류면접 (심영섭_대면)* | E28: 10:00 서류면접(장신혜) | F28: 10:30 서류면접 (심영섭)
A29: 10:30 서류면접(김지현_대면)* | B29: 12:00 서류면접 (심영섭_대면)* | C29: 11:00 서류면접 (범하나_대면)* | E29: 11:00 서류면접(장신혜) | F29: 11:30 서류면접 (심영섭)
A30: 11:30 서류면접(김지현_대면)* | C30: 12:00 서류면접 (범하나_대면)* | E30: 12:00 서류면접(장신혜)
A31: 12:30 서류면접(김지현_대면)* | C31: 13:00 서류면접 (범하나_대면)* | D31: 11:00 진로개발(김나영)
C32: 14:00 서류면접 (범하나_대면)* | D32: 12:00 진로개발(김나영) | E32: 10:30 서류면접(이상환)
B33: 12:30 서류면접 (김민경) | D33: 13:00 진로개발(김나영) | E33: 11:30 서류면접(이상환)
B34: 13:30 서류면접 (김민경)
A35: 13:00 서류면접(강 진_대면)*
A36: 14:00 서류면접 (강 진_대면)*
A37: 15:00 서류면접 (강 진_대면)* | E37: 10:30 외국계(지명선)
E38: 11:30 외국계(지명선)
E40: 18:00 서류면접 (김선화)
A43: 15 | B43: 16 | C43: 17 | D43: 18 | E43: 19 | F43: 20
...

Sheet 8월
A1: 45870
A2: 월요일 | B2: 화요일 | C2: 수요일 | D2: 목요일 | E2: 금요일 | F2: 토요일
E3: 1 | F3: 2 | G3: 진로취업 | H3: =COUNTIF($A:$F, "*진로취업*") -> 16 | I3: 강 진 | J3: =COUNTIF($A:$F, "*강 진*") -> 4
A4: 여름집중휴가기간 | G4: 서류면접 | H4: =COUNTIF($A:$F, "*서류면접*") -> 28 | I4: 김나영 | J4: =COUNTIF($A:$F, "*김나영*") -> 4
G5: 공기업 | H5: =COUNTIF($A:$F, "*공기업*") -> 1 | I5: 김미령 | J5: =COUNTIF($A:$F, "*김미령*") -> 0
G6: 외국계 | H6: =COUNTIF($A:$F, "*외국계*") -> 2 | I6: 김민경 | J6: =COUNTIF($A:$F, "*김민경*") -> 0
A7: 4 | B7: 5 | C7: 6 | D7: 7 | E7: 8 | F7: 9 | G7: 이공계 | H7: =COUNTIF($A:$F, "*이공계*") -> 4 | I7: 김선화 | J7: =COUNTIF($A:$F, "*김선화*") -> 6
G8: 콘텐츠 | H8: =COUNTIF($A:$F, "*콘텐츠*") -> 0 | I8: 김세희 | J8: =COUNTIF($A:$F, "*김세희*") -> 0
A9: 10:00 이공계(정지선) | C9: 10:00 진로취업 (한 나) | D9: 10:30 진로취업 (범하나) | E9: 10:00 서류면접(장신혜) | G9: 금융 | H9: =COUNTIF($A:$F, "*금융*") -> 0 | I9: 김지현 | J9: =COUNTIF($A:$F, "*김지현*") -> 4
A10: 11:00 이공계(정지선) | C10: 11:00 진로취업 (한 나) | D10: 11:30 진로취업 (범하나) | E10: 11:00 서류면접(장신혜) | G10: IT | H10: =COUNTIF($A:$F, "*IT*") -> 0 | I10: 범하나 | J10: =COUNTIF($A:$F, "*범하나*") -> 6
G11: 임원면접 | H11: =COUNTIF($A:$F, "*임원면접*") -> 0 | I11: 성지우 | J11: =COUNTIF($A:$F, "*성지우*") -> 0
G12: TOTAL | H12: =sum(H3:H11) -> 51 | I12: 신민이 | J12: =COUNTIF($A:$F, "*신민이*") -> 4
C13: 10:30 서류면접 (김선화) | I13: 심영섭 | J13: =COUNTIF($A:$F, "*심영섭*") -> 9
A14: 10:00 진로취업(신민이) | C14: 11:30 서류면접 (김선화) | E14: 9:30 서류면접 (이희영) | I14: 양우석 | J14: =COUNTIF($A:$F, "*양우석*") -> 0
A15: 11:00 진로취업(신민이) | E15: 10:30 서류면접 (이희영) | I15: 이상환 | J15: =COUNTIF($A:$F, "*이상환*") -> 0
I16: 이주환 | J16: =COUNTIF($A:$F, "*이주환*") -> 0
I17: 이하영 | J17: =COUNTIF($A:$F, "*이하영*") -> 0
D18: 11:00 진로취업(김나영) | I18: 이효숙 | J18: =COUNTIF($A:$F, "*이효숙*") -> 0
A19: 10:10 서류면접(강 진) | D19: 12:00 진로취업(김나영) | I19: 이희영 | J19: =COUNTIF($A:$F, "*이희영*") -> 2
A20: 11:10 서류면접(강 진) | I20: 장신혜 | J20: =COUNTIF($A:$F, "*장신혜*") -> 2
I21: 정지선 | J21: =COUNTIF($A:$F, "*정지선*") -> 4
I22: 지명선 | J22: =COUNTIF($A:$F, "*지명선*") -> 2
D23: 10:00 외국계(지명선) | I23: 최은주 | J23: =COUNTIF($A:$F, "*최은주*") -> 0
D24: 11:00 외국계(지명선) | I24: 한 나 | J24: =COUNTIF($A:$F, "*한 나*") -> 4
A25: 10:00 서류면접 (김지현) | I25: 민현정 | J25: =COUNTIF($A:$F, "*민현정*") -> 0
A26: 11:00 서류면접 (김지현) | I26: TOTAL | J26: =sum(J3:J25) -> 51
A30: 11 | B30: 12 | C30: 13 | D30: 14 | E30: 15 | F30: 16
E31: 광복절
A33: 10:00 이공계(정지선) | B33: 11:00 공기업 (심영섭) | C33: 10:00 진로취업 (한 나) | D33: 10:30 진로취업 (범하나)
A34: 11:00 이공계(정지선) | B34: 12:00 서류면접 (심영섭) | C34: 11:00 진로취업 (한 나) | D34: 11:30 진로취업 (범하나)
B35: 14:00 서류면접 (심영섭)
C37: 10:30 서류면접 (김선화)
B38: 10:00 진로취업(신민이) | C38: 11:30 서류면접 (김선화)
B39: 11:00 진로취업(신민이)
D42: 11:00 진로취업(김나영)
A43: 10:10 서류면접(강 진) | D43: 12:00 진로취업(김나영)
A44: 11:10 서류면접(강 진)
D46: 11:00 서류면접 (심영섭)
D47: 12:00 서류면접 (심영섭)
B48: 10:00 서류면접 (김지현) | D48: 14:00 서류면접 (심영섭)
...

Sheet 7월
A1: 45839
A2: 월요일 | B2: 화요일 | C2: 수요일 | D2: 목요일 | E2: 금요일 | F2: 토요일
B3: 1 | C3: 2 | D3: 3 | E3: 4 | F3: 5 | G3: 진로취업 | H3: =COUNTIF($A:$F, "*진로취업*") -> 21 | I3: 강 진 | J3: =COUNTIF($A:$F, "*강 진*") -> 4
G4: 서류면접 | H4: =COUNTIF($A:$F, "*서류면접*") -> 26 | I4: 김나영 | J4: =COUNTIF($A:$F, "*김나영*") -> 6
B5: 11:00 공기업 (심영섭) | C5: 10:00 진로취업 (한 나) | D5: 10:30 진로취업 (범하나) | E5: 10:00 서류면접(장신혜) | G5: 공기업 | H5: =COUNTIF($A:$F, "*공기업*") -> 2 | I5: 김미령 | J5: =COUNTIF($A:$F, "*김미령*") -> 0
B6: 12:00 서류면접 (심영섭) | C6: 11:00 진로취업 (한 나) | D6: 11:30 진로취업 (범하나) | E6: 11:00 서류면접(장신혜) | G6: 외국계 | H6: =COUNTIF($A:$F, "*외국계*") -> 4 | I6: 김민경 | J6: =COUNTIF($A:$F, "*김민경*") -> 4
B7: 14:00 서류면접 (심영섭) | G7: 이공계 | H7: =COUNTIF($A:$F, "*이공계*") -> 1 | I7: 김선화 | J7: =COUNTIF($A:$F, "*김선화*") -> 4
G8: 콘텐츠 | H8: =COUNTIF($A:$F, "*콘텐츠*") -> 0 | I8: 김세희 | J8: =COUNTIF($A:$F, "*김세희*") -> 0
G9: 금융 | H9: =COUNTIF($A:$F, "*금융*") -> 0 | I9: 김지현 | J9: =COUNTIF($A:$F, "*김지현*") -> 6
G10: IT | H10: =COUNTIF($A:$F, "*IT*") -> 0 | I10: 범하나 | J10: =COUNTIF($A:$F, "*범하나*") -> 4
G11: 임원면접 | H11: =COUNTIF($A:$F, "*임원면접*") -> 0 | I11: 성지우 | J11: =COUNTIF($A:$F, "*성지우*") -> 0
G12: TOTAL | H12: =sum(H3:H11) -> 54 | I12: 신민이 | J12: =COUNTIF($A:$F, "*신민이*") -> 2
I13: 심영섭 | J13: =COUNTIF($A:$F, "*심영섭*") -> 6
I14: 양우석 | J14: =COUNTIF($A:$F, "*양우석*") -> 0
I15: 이상환 | J15: =COUNTIF($A:$F, "*이상환*") -> 0
I16: 이주환 | J16: =COUNTIF($A:$F, "*이주환*") -> 0
I17: 이하영 | J17: =COUNTIF($A:$F, "*이하영*") -> 0
I18: 이효숙 | J18: =COUNTIF($A:$F, "*이효숙*") -> 0
D19: 10:00 외국계(지명선) | I19: 이희영 | J19: =COUNTIF($A:$F, "*이희영*") -> 4
D20: 11:00 외국계(지명선) | I20: 장신혜 | J20: =COUNTIF($A:$F, "*장신혜*") -> 4
I21: 정지선 | J21: =COUNTIF($A:$F, "*정지선*") -> 2
I22: 지명선 | J22: =COUNTIF($A:$F, "*지명선*") -> 4
I23: 최은주 | J23: =COUNTIF($A:$F, "*최은주*") -> 0
A24: 7 | B24: 8 | C24: 9 | D24: 10 | E24: 11 | F24: 12 | I24: 한 나 | J24: =COUNTIF($A:$F, "*한 나*") -> 4
I25: 민현정 | J25: =COUNTIF($A:$F, "*민현정*") -> 0
I26: TOTAL | J26: =sum(J3:J25) -> 54
C30: 10:30 서류면접 (김선화)
C31: 11:30 서류면접 (김선화) | E31: 9:30 서류면접 (이희영)
B32: 10:00 진로취업 (김민경) | E32: 10:30 서류면접 (이희영)
B33: 11:00 진로취업 (김민경)
D35: 11:00 진로취업(김나영)
A36: 10:10 서류면접(강 진) | D36: 12:00 진로취업(김나영)
A37: 11:10 서류면접(강 진) | D37: 13:00 진로취업(김나영)
B42: 10:00 서류면접 (김지현)
B43: 11:00 서류면접 (김지현)
A47: 14 | B47: 15 | C47: 16 | D47: 17 | E47: 18 | F47: 19
A48: 10:00 이공계(정지선)
A49: 11:00 진로취업(정지선) | B49: 11:00 공기업 (심영섭) | C49: 10:00 진로취업 (한 나) | D49: 10:30 진로취업 (범하나) | E49: 10:00 서류면접(장신혜)
B50: 12:00 서류면접 (심영섭) | C50: 11:00 진로취업 (한 나) | D50: 11:30 진로취업 (범하나) | E50: 11:00 서류면접(장신혜)
B51: 14:00 서류면접 (심영섭)
...

Sheet 6월
A1: 45809
A2: 월요일 | B2: 화요일 | C2: 수요일 | D2: 목요일 | E2: 금요일 | F2: 토요일
A3: 2 | B3: 3 | C3: 4 | D3: 5 | E3: 6 | F3: 7 | G3: 진로취업 | H3: =COUNTIF($A:$F, "*진로취업*") -> 18 | I3: 강 진 | J3: =COUNTIF($A:$F, "*강 진*") -> 6
E4: 현충일 | G4: 서류면접 | H4: =COUNTIF($A:$F, "*서류면접*") -> 34 | I4: 김나영 | J4: =COUNTIF($A:$F, "*김나영*") -> 6
A5: 기말고사 | G5: 공기업 | H5: =COUNTIF($A:$F, "*공기업*") -> 1 | I5: 김미령 | J5: =COUNTIF($A:$F, "*김미령*") -> 0
G6: 외국계 | H6: =COUNTIF($A:$F, "*외국계*") -> 4 | I6: 김민경 | J6: =COUNTIF($A:$F, "*김민경*") -> 4
G7: 이공계 | H7: =COUNTIF($A:$F, "*이공계*") -> 5 | I7: 김선화 | J7: =COUNTIF($A:$F, "*김선화*") -> 4
G8: 콘텐츠 | H8: =COUNTIF($A:$F, "*콘텐츠*") -> 0 | I8: 김세희 | J8: =COUNTIF($A:$F, "*김세희*") -> 0
G9: 금융 | H9: =COUNTIF($A:$F, "*금융*") -> 0 | I9: 김지현 | J9: =COUNTIF($A:$F, "*김지현*") -> 4
G10: IT | H10: =COUNTIF($A:$F, "*IT*") -> 0 | I10: 범하나 | J10: =COUNTIF($A:$F, "*범하나*") -> 4
G11: 임원면접 | H11: =COUNTIF($A:$F, "*임원면접*") -> 0 | I11: 성지우 | J11: =COUNTIF($A:$F, "*성지우*") -> 2
G12: TOTAL | H12: =sum(H3:H11) -> 62 | I12: 신민이 | J12: =COUNTIF($A:$F, "*신민이*") -> 6
I13: 심영섭 | J13: =COUNTIF($A:$F, "*심영섭*") -> 6
I14: 양우석 | J14: =COUNTIF($A:$F, "*양우석*") -> 0
I15: 이상환 | J15: =COUNTIF($A:$F, "*이상환*") -> 0
I16: 이주환 | J16: =COUNTIF($A:$F, "*이주환*") -> 0
I17: 이하영 | J17: =COUNTIF($A:$F, "*이하영*") -> 0
I18: 이효숙 | J18: =COUNTIF($A:$F, "*이효숙*") -> 0
I19: 이희영 | J19: =COUNTIF($A:$F, "*이희영*") -> 4
I20: 장신혜 | J20: =COUNTIF($A:$F, "*장신혜*") -> 4
I21: 정지선 | J21: =COUNTIF($A:$F, "*정지선*") -> 6
I22: 지명선 | J22: =COUNTIF($A:$F, "*지명선*") -> 2
I23: 최은주 | J23: =COUNTIF($A:$F, "*최은주*") -> 0
I24: 한 나 | J24: =COUNTIF($A:$F, "*한 나*") -> 4
I25: 민현정 | J25: =COUNTIF($A:$F, "*민현정*") -> 0
I26: TOTAL | J26: =sum(J3:J25) -> 62
A28: 9 | B28: 10 | C28: 11 | D28: 12 | E28: 13 | F28: 14
A30: 기말고사
A53: 16 | B53: 17 | C53: 18 | D53: 19 | E53: 20 | F53: 21
A55: 10:00 이공계(정지선) | B55: 11:00 공기업 (심영섭) | C55: 10:00 서류면접 (한 나) | D55: 10:30 서류면접 (범하나) | E55: 10:00 서류면접(장신혜)
A56: 11:00 이공계(정지선) | B56: 12:00 서류면접 (심영섭) | C56: 11:00 진로취업 (한 나) | D56: 11:30 서류면접 (범하나) | E56: 11:00 서류면접(장신혜)
B57: 14:00 서류면접 (심영섭)
C59: 10:30 서류면접 (김선화)
A60: 10:00 진로취업(신민이) | C60: 11:30 서류면접 (김선화) | E60: 9:30 서류면접 (이희영)
A61: 11:00 진로취업(신민이) | B61: 10:00 진로취업 (김민경) | E61: 10:30 서류면접 (이희영)
B62: 11:00 서류면접 (김민경)
D64: 11:00 진로취업(김나영)
A65: 10:10 서류면접(강 진) | D65: 12:00 진로취업(김나영)
A66: 11:10 서류면접(강 진) | D66: 13:00 진로취업(김나영)
D69: 16:00 외국계(지명선)
...

Sheet 5월
A1: 45778
A2: 월요일 | B2: 화요일 | C2: 수요일 | D2: 목요일 | E2: 금요일 | F2: 토요일
D3: 1 | E3: 2 | F3: 3 | G3: 진로취업 | H3: =COUNTIF($A:$F, "*진로취업*") -> 17 | I3: 강 진 | J3: =COUNTIF($A:$F, "*강 진*") -> 11
D4: 근로자의 날 | G4: 서류면접 | H4: =COUNTIF($A:$F, "*서류면접*") -> 89 | I4: 김나영 | J4: =COUNTIF($A:$F, "*김나영*") -> 12
D5: 중간고사 | G5: 공기업 | H5: =COUNTIF($A:$F, "*공기업*") -> 4 | I5: 김미령 | J5: =COUNTIF($A:$F, "*김미령*") -> 0
G6: 외국계 | H6: =COUNTIF($A:$F, "*외국계*") -> 9 | I6: 김민경 | J6: =COUNTIF($A:$F, "*김민경*") -> 6
E7: 10:00 서류면접(장신혜) | F7: 9:00 이공계(김세희) | G7: 이공계 | H7: =COUNTIF($A:$F, "*이공계*") -> 12 | I7: 김선화 | J7: =COUNTIF($A:$F, "*김선화*") -> 8
E8: 11:00 서류면접(장신혜) | F8: 10:00 이공계(김세희) | G8: 콘텐츠 | H8: =COUNTIF($A:$F, "*콘텐츠*") -> 5 | I8: 김세희 | J8: =COUNTIF($A:$F, "*김세희*") -> 4
G9: 금융 | H9: =COUNTIF($A:$F, "*금융*") -> 0 | I9: 김지현 | J9: =COUNTIF($A:$F, "*김지현*") -> 7
G10: IT | H10: =COUNTIF($A:$F, "*IT*") -> 0 | I10: 범하나 | J10: =COUNTIF($A:$F, "*범하나*") -> 12
G11: 임원면접 | H11: =COUNTIF($A:$F, "*임원면접*") -> 9 | I11: 성지우 | J11: =COUNTIF($A:$F, "*성지우*") -> 4
E12: 9:30 서류면접 (이희영) | F12: 9:30 서류면접 (강 진) | G12: TOTAL | H12: =sum(H3:H11) -> 145 | I12: 신민이 | J12: =COUNTIF($A:$F, "*신민이*") -> 6
E13: 10:30 서류면접 (이희영) | F13: 10:30 서류면접 (강 진) | I13: 심영섭 | J13: =COUNTIF($A:$F, "*심영섭*") -> 11
I14: 양우석 | J14: =COUNTIF($A:$F, "*양우석*") -> 10
I15: 이상환 | J15: =COUNTIF($A:$F, "*이상환*") -> 8
F16: 10:00 서류면접 (심영섭) | I16: 이주환 | J16: =COUNTIF($A:$F, "*이주환*") -> 0
F17: 11:00 서류면접 (심영섭) | I17: 이하영 | J17: =COUNTIF($A:$F, "*이하영*") -> 0
I18: 이효숙 | J18: =COUNTIF($A:$F, "*이효숙*") -> 0
I19: 이희영 | J19: =COUNTIF($A:$F, "*이희영*") -> 12
I20: 장신혜 | J20: =COUNTIF($A:$F, "*장신혜*") -> 10
I21: 정지선 | J21: =COUNTIF($A:$F, "*정지선*") -> 11
I22: 지명선 | J22: =COUNTIF($A:$F, "*지명선*") -> 5
I23: 최은주 | J23: =COUNTIF($A:$F, "*최은주*") -> 0
I24: 한 나 | J24: =COUNTIF($A:$F, "*한 나*") -> 8
I25: 민현정 | J25: =COUNTIF($A:$F, "*민현정*") -> 0
I26: TOTAL | J26: =sum(J3:J25) -> 145
F29: 11:00 임원면접(양우석)
A32: 5 | B32: 6 | C32: 7 | D32: 8 | E32: 9 | F32: 10
A33: 어린이날/부처님 오신 날 | B33: 어린이날/부처님 오신 날 대체공휴일 | F33: 취업MC ONE-DAY(예정)
C35: 10:00 서류면접 (한 나) | D35: 10:30 서류면접 (범하나_대면)* | E35: 10:00 서류면접(장신혜)
C36: 11:00 서류면접 (한 나) | D36: 11:30 서류면접 (범하나_대면)* | E36: 11:00 서류면접(장신혜)
D37: 12:30 서류면접 (범하나_대면)* | E37: 12:00 서류면접(장신혜)
C39: 10:30 공기업 (김선화)
C40: 11:30 서류면접 (김선화) | D40: 10:30 콘텐츠엔터(이상환) | E40: 9:30 서류면접 (이희영)
D41: 11:30 콘텐츠엔터(이상환) | E41: 10:30 서류면접 (이희영)
E42: 11:30 서류면접 (이희영)
D44: 11:00 진로취업(김나영)
D45: 12:00 진로취업(김나영)
D46: 13:00 진로취업(김나영)
D49: 10:00 외국계(지명선)
...

Sheet 4월
A1: 45748
A2: 월요일 | B2: 화요일 | C2: 수요일 | D2: 목요일 | E2: 금요일 | F2: 토요일
B3: 1 | C3: 2 | D3: 3 | E3: 4 | F3: 5 | G3: 진로취업 | H3: =COUNTIF($A:$F, "*진로취업*") -> 16 | I3: 강 진 | J3: =COUNTIF($A:$F, "*강 진*") -> 6
G4: 서류면접 | H4: =COUNTIF($A:$F, "*서류면접*") -> 65 | I4: 김나영 | J4: =COUNTIF($A:$F, "*김나영*") -> 9
B5: 11:00 공기업 (심영섭_대면)* | C5: 10:00 서류면접 (한 나) | D5: 10:30 서류면접 (범하나_대면)* | E5: 10:00 서류면접(장신혜) | F5: 9:00 이공계(김세희) | G5: 공기업 | H5: =COUNTIF($A:$F, "*공기업*") -> 5 | I5: 김미령 | J5: =COUNTIF($A:$F, "*김미령*") -> 0
B6: 12:00 서류면접 (심영섭_대면)* | C6: 11:00 서류면접 (한 나) | D6: 11:30 서류면접 (범하나_대면)* | E6: 11:00 서류면접(장신혜) | F6: 10:00 이공계(김세희) | G6: 외국계 | H6: =COUNTIF($A:$F, "*외국계*") -> 5 | I6: 김민경 | J6: =COUNTIF($A:$F, "*김민경*") -> 8
B7: 14:00 서류면접 (심영섭_대면)* | D7: 12:30 서류면접 (범하나_대면)* | G7: 이공계 | H7: =COUNTIF($A:$F, "*이공계*") -> 15 | I7: 김선화 | J7: =COUNTIF($A:$F, "*김선화*") -> 6
G8: 콘텐츠 | H8: =COUNTIF($A:$F, "*콘텐츠*") -> 6 | I8: 김세희 | J8: =COUNTIF($A:$F, "*김세희*") -> 6
C9: 10:30 공기업 (김선화) | G9: 금융 | H9: =COUNTIF($A:$F, "*금융*") -> 0 | I9: 김지현 | J9: =COUNTIF($A:$F, "*김지현*") -> 6
C10: 11:30 서류면접 (김선화) | D10: 10:30 콘텐츠엔터(이상환) | E10: 9:30 서류면접 (이희영) | G10: IT | H10: =COUNTIF($A:$F, "*IT*") -> 0 | I10: 범하나 | J10: =COUNTIF($A:$F, "*범하나*") -> 9
B11: 10:00 서류면접 (김민경) | D11: 11:30 콘텐츠엔터(이상환) | E11: 10:30 진로취업 (이희영) | G11: 임원면접 | H11: =COUNTIF($A:$F, "*임원면접*") -> 0 | I11: 성지우 | J11: =COUNTIF($A:$F, "*성지우*") -> 2
B12: 11:00 서류면접 (김민경) | G12: TOTAL | H12: =sum(H3:H11) -> 112 | I12: 신민이 | J12: =COUNTIF($A:$F, "*신민이*") -> 6
I13: 심영섭 | J13: =COUNTIF($A:$F, "*심영섭*") -> 14
D14: 11:00 진로취업(김나영) | F14: 10:00 서류면접 (심영섭) | I14: 양우석 | J14: =COUNTIF($A:$F, "*양우석*") -> 0
D15: 12:00 진로취업(김나영) | F15: 11:00 서류면접 (심영섭) | I15: 이상환 | J15: =COUNTIF($A:$F, "*이상환*") -> 6
D16: 13:00 진로취업(김나영) | I16: 이주환 | J16: =COUNTIF($A:$F, "*이주환*") -> 0
I17: 이하영 | J17: =COUNTIF($A:$F, "*이하영*") -> 0
I18: 이효숙 | J18: =COUNTIF($A:$F, "*이효숙*") -> 0
D19: 11:00 외국계(지명선) | I19: 이희영 | J19: =COUNTIF($A:$F, "*이희영*") -> 8
I20: 장신혜 | J20: =COUNTIF($A:$F, "*장신혜*") -> 6
I21: 정지선 | J21: =COUNTIF($A:$F, "*정지선*") -> 11
I22: 지명선 | J22: =COUNTIF($A:$F, "*지명선*") -> 3
I23: 최은주 | J23: =COUNTIF($A:$F, "*최은주*") -> 0
I24: 한 나 | J24: =COUNTIF($A:$F, "*한 나*") -> 6
I25: 민현정 | J25: =COUNTIF($A:$F, "*민현정*") -> 0
A26: 7 | B26: 8 | C26: 9 | D26: 10 | E26: 11 | F26: 12 | I26: TOTAL | J26: =sum(J3:J25) -> 112
A28: 10:00 이공계(정지선_대면)* | B28: 11:00 서류면접 (심영섭)* | C28: 10:00 서류면접 (한 나) | D28: 10:30 서류면접 (범하나_대면)* | E28: 10:00 서류면접(장신혜) | F28: 9:00 이공계(김세희)
A29: 11:00 이공계(정지선_대면)* | B29: 12:00 서류면접 (심영섭_대면)* | C29: 11:00 서류면접 (한 나) | D29: 11:30 서류면접 (범하나_대면)* | E29: 11:00 서류면접(장신혜) | F29: 10:00 이공계(김세희)
A30: 12:00 이공계(정지선_대면)* | B30: 14:00 서류면접 (심영섭_대면)* | D30: 12:30 서류면접 (범하나_대면)*
A33: 10:00 진로취업(신민이) | D33: 10:30 콘텐츠엔터(이상환) | E33: 9:30 서류면접 (이희영)
A34: 11:00 진로취업(신민이) | B34: 10:00 서류면접 (김민경) | D34: 11:30 콘텐츠엔터(이상환) | E34: 10:30 서류면접 (이희영)
B35: 11:00 서류면접 (김민경)
C36: 15:00 외국계(성지우)
C37: 16:00 외국계(성지우) | D37: 11:00 진로취업(김나영) | E37: 10:30 공기업 (김선화)
A38: 10:10 서류면접(강 진_대면)* | B38: 10:30 서류면접 (김선화) | D38: 12:00 진로취업(김나영) | E38: 11:30 서류면접 (김선화)
A39: 11:10 서류면접(강 진_대면)* | B39: 11:30 서류면접 (김선화) | D39: 13:00 진로취업(김나영)
A40: 12:10 서류면접(강 진_대면)*
F41: 9:00 서류면접 (이희영)
F42: 10:00 서류면접 (이희영)
C44: 10:00 서류면접 (김지현)
...

Sheet 3월
A1: 45717
A2: 월요일 | B2: 화요일 | C2: 수요일 | D2: 목요일 | E2: 금요일 | F2: 토요일
F3: 1 | G3: 진로취업 | H3: =COUNTIF($A:$F, "*진로취업*") -> 24 | I3: 강 진 | J3: =COUNTIF($A:$F, "*강 진*") -> 25
F4: 삼일절 | G4: 서류면접 | H4: =COUNTIF($A:$F, "*서류면접*") -> 134 | I4: 김나영 | J4: =COUNTIF($A:$F, "*김나영*") -> 14
G5: 공기업 | H5: =COUNTIF($A:$F, "*공기업*") -> 5 | I5: 김미령 | J5: =COUNTIF($A:$F, "*김미령*") -> 0
G6: 외국계 | H6: =COUNTIF($A:$F, "*외국계*") -> 10 | I6: 김민경 | J6: =COUNTIF($A:$F, "*김민경*") -> 8
A7: 3 | B7: 4 | C7: 5 | D7: 6 | E7: 7 | F7: 8 | G7: 이공계 | H7: =COUNTIF($A:$F, "*이공계*") -> 28 | I7: 김선화 | J7: =COUNTIF($A:$F, "*김선화*") -> 10
A8: 대체공휴일 | G8: 콘텐츠 | H8: =COUNTIF($A:$F, "*콘텐츠*") -> 8 | I8: 김세희 | J8: =COUNTIF($A:$F, "*김세희*") -> 8
B9: 11:00 공기업 (심영섭_대면)* | C9: 10:00 서류면접 (한 나) | D9: 10:30 서류면접 (범하나_대면)* | E9: 10:00 서류면접(장신혜) | F9: 9:00 이공계(김세희) | G9: 금융 | H9: =COUNTIF($A:$F, "*금융*") -> 0 | I9: 김지현 | J9: =COUNTIF($A:$F, "*김지현*") -> 11
B10: 12:00 서류면접 (심영섭_대면)* | C10: 11:00 서류면접 (한 나) | D10: 11:30 서류면접 (범하나_대면)* | E10: 11:00 서류면접(장신혜) | F10: 10:00 이공계(김세희) | G10: IT | H10: =COUNTIF($A:$F, "*IT*") -> 0 | I10: 범하나 | J10: =COUNTIF($A:$F, "*범하나*") -> 17
B11: 14:00 서류면접 (심영섭_대면)* | D11: 12:30 서류면접 (범하나_대면)* | E11: 12:00 서류면접(장신혜) | G11: 임원면접 | H11: =COUNTIF($A:$F, "*임원면접*") -> 0 | I11: 성지우 | J11: =COUNTIF($A:$F, "*성지우*") -> 5
B12: 15:00 서류면접 (심영섭_대면)* | D12: 13:30 서류면접 (범하나_대면)* | G12: TOTAL | H12: =sum(H3:H11) -> 209 | I12: 신민이 | J12: =COUNTIF($A:$F, "*신민이*") -> 9
C13: 10:30 공기업 (김선화) | I13: 심영섭 | J13: =COUNTIF($A:$F, "*심영섭*") -> 26
C14: 11:30 서류면접 (김선화) | D14: 10:30 콘텐츠엔터(이상환) | E14: 9:30 서류면접 (이희영) | F14: 9:30 서류면접 (강 진) | I14: 양우석 | J14: =COUNTIF($A:$F, "*양우석*") -> 0
D15: 11:30 콘텐츠엔터(이상환) | E15: 10:30 서류면접 (이희영) | F15: 10:30 서류면접 (강 진) | I15: 이상환 | J15: =COUNTIF($A:$F, "*이상환*") -> 8
E16: 11:30 서류면접 (이희영) | I16: 이주환 | J16: =COUNTIF($A:$F, "*이주환*") -> 0
C17: 10:00 서류면접 (김민경) | I17: 이하영 | J17: =COUNTIF($A:$F, "*이하영*") -> 0
C18: 11:00 서류면접 (김민경) | D18: 11:00 진로취업(김나영) | F18: 10:00 서류면접 (심영섭) | I18: 이효숙 | J18: =COUNTIF($A:$F, "*이효숙*") -> 0
B19: 10:00 이공계(정지선_대면)* | D19: 12:00 진로취업(김나영) | F19: 11:00 서류면접 (심영섭) | I19: 이희영 | J19: =COUNTIF($A:$F, "*이희영*") -> 21
B20: 11:00 이공계(정지선_대면)* | D20: 13:00 진로취업(김나영) | F20: 12:00 공기업 (심영섭) | I20: 장신혜 | J20: =COUNTIF($A:$F, "*장신혜*") -> 12
B21: 12:00 이공계(정지선_대면)* | I21: 정지선 | J21: =COUNTIF($A:$F, "*정지선*") -> 22
B22: 13:00 이공계(정지선_대면)* | D22: 10:00 외국계(지명선) | F22: 9:00 서류면접 (이희영) | I22: 지명선 | J22: =COUNTIF($A:$F, "*지명선*") -> 5
D23: 11:00 외국계(지명선) | F23: 10:00 서류면접 (이희영) | I23: 최은주 | J23: =COUNTIF($A:$F, "*최은주*") -> 0
I24: 한 나 | J24: =COUNTIF($A:$F, "*한 나*") -> 8
I25: 민현정 | J25: =COUNTIF($A:$F, "*민현정*") -> 0
F26: 9:30 이공계(정지선) | I26: TOTAL | J26: =sum(J3:J25) -> 209
F27: 10:30 이공계(정지선)
F28: 11:30 이공계(정지선)
A30: 10 | B30: 11 | C30: 12 | D30: 13 | E30: 14 | F30: 15
A32: 9:30 이공계(정지선) | B32: 11:00 서류면접 (심영섭_대면)* | C32: 10:00 서류면접 (한 나) | D32: 10:30 서류면접 (범하나_대면)* | E32: 10:00 서류면접(장신혜) | F32: 9:00 서류면접(김세희)
A33: 10:30 이공계(정지선) | B33: 12:00 서류면접 (심영섭_대면)* | C33: 11:00 서류면접 (한 나) | D33: 11:30 서류면접 (범하나_대면)* | E33: 11:00 서류면접(장신혜) | F33: 10:00 이공계(김세희)
B34: 14:00 서류면접 (심영섭_대면)* | C34: 12:00 서류면접 (한 나) | D34: 12:30 서류면접 (범하나_대면)* | E34: 12:00 서류면접(장신혜)
B35: 15:00 서류면접 (심영섭_대면)* | C35: 13:00 서류면접 (한 나) | D35: 13:30 서류면접 (범하나_대면)*
D36: 14:30 서류면접 (범하나_대면)*
A37: 10:00 진로취업(신민이) | C37: 9:30 서류면접 (김선화) | E37: 9:30 서류면접 (이희영) | F37: 9:30 서류면접 (강 진)
A38: 11:00 진로취업(신민이) | B38: 10:00 서류면접 (김민경) | C38: 10:30 서류면접 (김선화) | D38: 10:30 콘텐츠엔터(이상환) | E38: 10:30 서류면접 (이희영) | F38: 10:30 서류면접 (강 진)
A39: 16:00 진로취업(신민이) | B39: 11:00 서류면접 (김민경) | C39: 11:30 서류면접 (김선화) | D39: 11:30 콘텐츠엔터(이상환) | E39: 11:30 서류면접 (이희영) | F39: 11:30 서류면접 (강 진)
C40: 12:30 서류면접 (김선화) | E40: 12:30 서류면접 (이희영) | F40: 12:30 서류면접 (강 진)
D41: 11:00 진로취업(김나영)
A42: 10:10 서류면접(강 진_대면)* | C42: 15:00 외국계(성지우) | D42: 12:00 진로취업(김나영) | F42: 9:10 서류면접 (심영섭)
...

Sheet 2026-1월
A1: 46023
A2: 월요일 | B2: 화요일 | C2: 수요일 | D2: 목요일 | E2: 금요일 | F2: 토요일
D3: 1 | E3: 2 | F3: 3 | G3: 진로개발 | H3: =COUNTIF($A:$F, "*진로개발*") -> 28 | I3: 강 진 | J3: =COUNTIF($A:$F, "*강 진*") -> 4
D4: 연초 | G4: 서류면접 | H4: =COUNTIF($A:$F, "*서류면접*") -> 28 | I4: 김나영 | J4: =COUNTIF($A:$F, "*김나영*") -> 8
G5: 공기업 | H5: =COUNTIF($A:$F, "*공기업*") -> 5 | I5: 김미령 | J5: =COUNTIF($A:$F, "*김미령*") -> 0
G6: 외국계 | H6: =COUNTIF($A:$F, "*외국계*") -> 8 | I6: 김민경 | J6: =COUNTIF($A:$F, "*김민경*") -> 2
G7: 이공계 | H7: =COUNTIF($A:$F, "*이공계*") -> 2 | I7: 김선화 | J7: =COUNTIF($A:$F, "*김선화*") -> 6
G8: 콘텐츠 | H8: =COUNTIF($A:$F, "*콘텐츠*") -> 0 | I8: 김세희 | J8: =COUNTIF($A:$F, "*김세희*") -> 0
G9: 금융 | H9: =COUNTIF($A:$F, "*금융*") -> 0 | I9: 김지현 | J9: =COUNTIF($A:$F, "*김지현*") -> 4
G10: IT | H10: =COUNTIF($A:$F, "*IT*") -> 0 | I10: 범하나 | J10: =COUNTIF($A:$F, "*범하나*") -> 5
G11: 임원면접 | H11: =COUNTIF($A:$F, "*임원면접*") -> 0 | I11: 성지우 | J11: =COUNTIF($A:$F, "*성지우*") -> 4
G12: TOTAL | H12: =sum(H3:H11) -> 71 | I12: 신민이 | J12: =COUNTIF($A:$F, "*신민이*") -> 5
I13: 심영섭 | J13: =COUNTIF($A:$F, "*심영섭*") -> 8
I14: 양우석 | J14: =COUNTIF($A:$F, "*양우석*") -> 0
I15: 이상환 | J15: =COUNTIF($A:$F, "*이상환*") -> 0
I16: 이주환 | J16: =COUNTIF($A:$F, "*이주환*") -> 0
A17: 5 | B17: 6 | C17: 7 | D17: 8 | E17: 9 | F17: 10 | I17: 이하영 | J17: =COUNTIF($A:$F, "*이하영*") -> 0
A18: 10:30 진로개발(김지현) | B18: 10:00 공기업 (심영섭) | C18: 11:00 진로개발 (범하나) | D18: 11:00 진로개발(김나영) | E18: 10:00 서류면접(장신혜) | I18: 이효숙 | J18: =COUNTIF($A:$F, "*이효숙*") -> 0
A19: 11:30 진로개발(김지현) | B19: 11:00 서류면접 (심영섭) | C19: 12:00 진로개발 (범하나) | D19: 12:00 진로개발(김나영) | E19: 11:00 서류면접(장신혜) | I19: 이희영 | J19: =COUNTIF($A:$F, "*이희영*") -> 9
I20: 장신혜 | J20: =COUNTIF($A:$F, "*장신혜*") -> 6
I21: 정지선 | J21: =COUNTIF($A:$F, "*정지선*") -> 2
E22: 10:30 외국계(지명선) | I22: 지명선 | J22: =COUNTIF($A:$F, "*지명선*") -> 4
E23: 11:30 외국계(지명선) | I23: 최은주 | J23: =COUNTIF($A:$F, "*최은주*") -> 0
I24: 한 나 | J24: =COUNTIF($A:$F, "*한 나*") -> 4
I25: 민현정 | J25: =COUNTIF($A:$F, "*민현정*") -> 0
I26: TOTAL | J26: =sum(J3:J25) -> 71
A37: 12 | B37: 13 | C37: 14 | D37: 15 | E37: 16 | F37: 17
B38: 10:00 진로개발(신민이) | C38: 10:00 진로개발 (한 나) | D38: 10:00 공기업 (김선화) | E38: 10:30 서류면접 (이희영)
A39: 11:00 이공계(정지선) | B39: 11:00 진로개발(신민이) | C39: 11:00 진로개발 (한 나) | D39: 11:00 서류면접 (김선화) | E39: 11:30 서류면접 (이희영)
A40: 12:00 이공계(정지선) | D40: 12:00 서류면접 (김선화) | E40: 12:30 서류면접 (이희영)
B43: 11:30 진로개발 (김민경)
B44: 12:30 진로개발 (김민경)
C46: 16:00 외국계(성지우)
C47: 17:00 외국계(성지우)
A56: 19 | B56: 20 | C56: 21 | D56: 22 | E56: 23 | F56: 24
A57: 10:30 진로개발(김지현) | B57: 10:00 공기업 (심영섭) | C57: 11:00 진로개발 (범하나) | D57: 11:00 진로개발(김나영) | E57: 10:00 서류면접(장신혜)
A58: 11:30 진로개발(김지현) | B58: 11:00 서류면접 (심영섭) | C58: 12:00 진로개발 (범하나) | D58: 12:00 진로개발(김나영) | E58: 11:00 서류면접(장신혜)
B59: 12:00 서류면접 (심영섭) | C59: 13:00 진로개발 (범하나) | D59: 13:00 진로개발(김나영) | E59: 12:00 서류면접(장신혜)
E60: 14:00 서류면접(장신혜)
C61: 10:00 서류면접 (이희영)
...

Sheet 2026-2월
A1: 46054
A2: 월요일 | B2: 화요일 | C2: 수요일 | D2: 목요일 | E2: 금요일 | F2: 토요일
A3: 2 | B3: 3 | C3: 4 | D3: 5 | E3: 6 | F3: 7 | G3: 진로개발 | H3: =COUNTIF($A:$F, "*진로개발*") -> 12 | I3: 강 진 | J3: =COUNTIF($A:$F, "*강 진*") -> 4
A4: 10:00 이공계(정지선) | B4: 10:00 진로개발(신민이) | D4: 10:00 공기업 (김선화) | E4: 10:00 서류면접(장신혜) | G4: 서류면접 | H4: =COUNTIF($A:$F, "*서류면접*") -> 11 | I4: 김나영 | J4: =COUNTIF($A:$F, "*김나영*") -> 3
A5: 11:00 이공계(정지선) | B5: 11:00 진로개발(신민이) | D5: 11:00 서류면접 (김선화) | E5: 11:00 서류면접(장신혜) | G5: 공기업 | H5: =COUNTIF($A:$F, "*공기업*") -> 2 | I5: 김미령 | J5: =COUNTIF($A:$F, "*김미령*") -> 0
A6: 12:00 이공계(정지선) | B6: 12:00 진로개발(신민이) | D6: 12:00 서류면접 (김선화) | E6: 12:00 서류면접(장신혜) | G6: 외국계 | H6: =COUNTIF($A:$F, "*외국계*") -> 2 | I6: 김민경 | J6: =COUNTIF($A:$F, "*김민경*") -> 0
C7: 10:00 진로개발 (범하나) | G7: 이공계 | H7: =COUNTIF($A:$F, "*이공계*") -> 3 | I7: 김선화 | J7: =COUNTIF($A:$F, "*김선화*") -> 3
B8: 10:00 공기업 (심영섭) | C8: 11:00 진로개발 (범하나) | D8: 11:00 진로개발(김나영) | G8: 콘텐츠 | H8: =COUNTIF($A:$F, "*콘텐츠*") -> 0 | I8: 김세희 | J8: =COUNTIF($A:$F, "*김세희*") -> 0
B9: 11:00 서류면접 (심영섭) | C9: 12:00 진로개발 (범하나) | D9: 12:00 진로개발(김나영) | E9: 10:00 서류면접(강 진) | G9: 금융 | H9: =COUNTIF($A:$F, "*금융*") -> 0 | I9: 김지현 | J9: =COUNTIF($A:$F, "*김지현*") -> 0
B10: 12:00 서류면접 (심영섭) | C10: 13:00 진로개발 (범하나) | D10: 13:00 진로개발(김나영) | E10: 11:00 서류면접(강 진) | G10: IT | H10: =COUNTIF($A:$F, "*IT*") -> 0 | I10: 범하나 | J10: =COUNTIF($A:$F, "*범하나*") -> 4
E11: 13:00 서류면접(강 진) | G11: 임원면접 | H11: =COUNTIF($A:$F, "*임원면접*") -> 0 | I11: 성지우 | J11: =COUNTIF($A:$F, "*성지우*") -> 2
E12: 14:00 서류면접(강 진) | G12: TOTAL | H12: =sum(H3:H11) -> 30 | I12: 신민이 | J12: =COUNTIF($A:$F, "*신민이*") -> 5
I13: 심영섭 | J13: =COUNTIF($A:$F, "*심영섭*") -> 3
I14: 양우석 | J14: =COUNTIF($A:$F, "*양우석*") -> 0
I15: 이상환 | J15: =COUNTIF($A:$F, "*이상환*") -> 0
I16: 이주환 | J16: =COUNTIF($A:$F, "*이주환*") -> 0
I17: 이하영 | J17: =COUNTIF($A:$F, "*이하영*") -> 0
I18: 이효숙 | J18: =COUNTIF($A:$F, "*이효숙*") -> 0
I19: 이희영 | J19: =COUNTIF($A:$F, "*이희영*") -> 0
I20: 장신혜 | J20: =COUNTIF($A:$F, "*장신혜*") -> 3
A21: 9 | B21: 10 | C21: 11 | D21: 12 | E21: 13 | F21: 14 | I21: 정지선 | J21: =COUNTIF($A:$F, "*정지선*") -> 3
B22: 10:00 진로개발(신민이) | I22: 지명선 | J22: =COUNTIF($A:$F, "*지명선*") -> 0
B23: 11:00 진로개발(신민이) | I23: 최은주 | J23: =COUNTIF($A:$F, "*최은주*") -> 0
I24: 한 나 | J24: =COUNTIF($A:$F, "*한 나*") -> 0
I25: 민현정 | J25: =COUNTIF($A:$F, "*민현정*") -> 0
B26: 16:00 외국계(성지우) | I26: TOTAL | J26: =sum(J3:J25) -> 30
B27: 17:00 외국계(성지우)
A39: 16 | B39: 17 | C39: 18 | D39: 19 | E39: 20 | F39: 21
A40: 설연휴 | D40: 2025학년도 종료
A59: 23 | B59: 24 | C59: 25 | D59: 26 | E59: 27 | F59: 28
A60: 2025학년도 종료

Sheet 요약
B1: 2025학년도 월별 진로·취업컨설팅 현황
B2: 유형별 | C2: 3월 | D2: 4월 | E2: 5월 | F2: 6월 | G2: 7월 | H2: 8월 | I2: 9월 | J2: 10월 | K2: 11월 | L2: 12월 | M2: 1월 | N2: 2월 | O2: 합계
B3: 진로취업 | C3: =VLOOKUP($B3,'3월'!$G$3:$H$11,2, false) -> 24 | D3: =VLOOKUP($B3,'4월'!$G$3:$H$11,2, false) -> 16 | E3: =VLOOKUP($B3,'5월'!$G$3:$H$11,2, false) -> 17 | F3: =VLOOKUP($B3,'6월'!$G$3:$H$11,2, false) -> 18 | G3: =VLOOKUP($B3,'7월'!$G$3:$H$11,2, false) -> 21 | H3: =VLOOKUP($B3,'8월'!$G$3:$H$11,2, false) -> 16 | O3: =sum(C3:N3) -> 112 | P3: =sum(O3:O4) -> 223
B4: 진로개발 | I4: =VLOOKUP($B4,'9월'!$G$3:$H$11,2, false) -> 22 | J4: =VLOOKUP($B4,'10월'!$G$3:$H$11,2, false) -> 15 | K4: =VLOOKUP($B4,'11월'!$G$3:$H$11,2, false) -> 19 | L4: =VLOOKUP($B4,'12월'!$G$3:$H$11,2, false) -> 15 | M4: =VLOOKUP($B4,'2026-1월'!$G$3:$H$11,2, false) -> 28 | N4: =VLOOKUP($B4,'2026-2월'!$G$3:$H$11,2, false) -> 12 | O4: =sum(C4:N4) -> 111
B5: 서류면접 | C5: =VLOOKUP($B5,'3월'!$G$3:$H$11,2, false) -> 134 | D5: =VLOOKUP($B5,'4월'!$G$3:$H$11,2, false) -> 65 | E5: =VLOOKUP($B5,'5월'!$G$3:$H$11,2, false) -> 89 | F5: =VLOOKUP($B5,'6월'!$G$3:$H$11,2, false) -> 34 | G5: =VLOOKUP($B5,'7월'!$G$3:$H$11,2, false) -> 26 | H5: =VLOOKUP($B5,'8월'!$G$3:$H$11,2, false) -> 28 | I5: =VLOOKUP($B5,'9월'!$G$3:$H$11,2, false) -> 130 | J5: =VLOOKUP($B5,'10월'!$G$3:$H$11,2, false) -> 51 | K5: =VLOOKUP($B5,'11월'!$G$3:$H$11,2, false) -> 110 | L5: =VLOOKUP($B5,'12월'!$G$3:$H$11,2, false) -> 38 | M5: =VLOOKUP($B5,'2026-1월'!$G$3:$H$11,2, false) -> 28 | N5: =VLOOKUP($B5,'2026-2월'!$G$3:$H$11,2, false) -> 11 | O5: =sum(C5:N5) -> 744
B6: 공기업 | C6: =VLOOKUP($B6,'3월'!$G$3:$H$11,2, false) -> 5 | D6: =VLOOKUP($B6,'4월'!$G$3:$H$11,2, false) -> 5 | E6: =VLOOKUP($B6,'5월'!$G$3:$H$11,2, false) -> 4 | F6: =VLOOKUP($B6,'6월'!$G$3:$H$11,2, false) -> 1 | G6: =VLOOKUP($B6,'7월'!$G$3:$H$11,2, false) -> 2 | H6: =VLOOKUP($B6,'8월'!$G$3:$H$11,2, false) -> 1 | I6: =VLOOKUP($B6,'9월'!$G$3:$H$11,2, false) -> 6 | J6: =VLOOKUP($B6,'10월'!$G$3:$H$11,2, false) -> 3 | K6: =VLOOKUP($B6,'11월'!$G$3:$H$11,2, false) -> 6 | L6: =VLOOKUP($B6,'12월'!$G$3:$H$11,2, false) -> 4 | M6: =VLOOKUP($B6,'2026-1월'!$G$3:$H$11,2, false) -> 5 | N6: =VLOOKUP($B6,'2026-2월'!$G$3:$H$11,2, false) -> 2 | O6: =sum(C6:N6) -> 44
B7: 외국계 | C7: =VLOOKUP($B7,'3월'!$G$3:$H$11,2, false) -> 10 | D7: =VLOOKUP($B7,'4월'!$G$3:$H$11,2, false) -> 5 | E7: =VLOOKUP($B7,'5월'!$G$3:$H$11,2, false) -> 9 | F7: =VLOOKUP($B7,'6월'!$G$3:$H$11,2, false) -> 4 | G7: =VLOOKUP($B7,'7월'!$G$3:$H$11,2, false) -> 4 | H7: =VLOOKUP($B7,'8월'!$G$3:$H$11,2, false) -> 2 | I7: =VLOOKUP($B7,'9월'!$G$3:$H$11,2, false) -> 8 | J7: =VLOOKUP($B7,'10월'!$G$3:$H$11,2, false) -> 4 | K7: =VLOOKUP($B7,'11월'!$G$3:$H$11,2, false) -> 7 | L7: =VLOOKUP($B7,'12월'!$G$3:$H$11,2, false) -> 5 | M7: =VLOOKUP($B7,'2026-1월'!$G$3:$H$11,2, false) -> 8 | N7: =VLOOKUP($B7,'2026-2월'!$G$3:$H$11,2, false) -> 2 | O7: =sum(C7:N7) -> 68
B8: 이공계 | C8: =VLOOKUP($B8,'3월'!$G$3:$H$11,2, false) -> 28 | D8: =VLOOKUP($B8,'4월'!$G$3:$H$11,2, false) -> 15 | E8: =VLOOKUP($B8,'5월'!$G$3:$H$11,2, false) -> 12 | F8: =VLOOKUP($B8,'6월'!$G$3:$H$11,2, false) -> 5 | G8: =VLOOKUP($B8,'7월'!$G$3:$H$11,2, false) -> 1 | H8: =VLOOKUP($B8,'8월'!$G$3:$H$11,2, false) -> 4 | I8: =VLOOKUP($B8,'9월'!$G$3:$H$11,2, false) -> 20 | J8: =VLOOKUP($B8,'10월'!$G$3:$H$11,2, false) -> 3 | K8: =VLOOKUP($B8,'11월'!$G$3:$H$11,2, false) -> 20 | L8: =VLOOKUP($B8,'12월'!$G$3:$H$11,2, false) -> 2 | M8: =VLOOKUP($B8,'2026-1월'!$G$3:$H$11,2, false) -> 2 | N8: =VLOOKUP($B8,'2026-2월'!$G$3:$H$11,2, false) -> 3 | O8: =sum(C8:N8) -> 115
B9: 콘텐츠 | C9: =VLOOKUP($B9,'3월'!$G$3:$H$11,2, false) -> 8 | D9: =VLOOKUP($B9,'4월'!$G$3:$H$11,2, false) -> 6 | E9: =VLOOKUP($B9,'5월'!$G$3:$H$11,2, false) -> 5 | F9: =VLOOKUP($B9,'6월'!$G$3:$H$11,2, false) -> 0 | G9: =VLOOKUP($B9,'7월'!$G$3:$H$11,2, false) -> 0 | H9: =VLOOKUP($B9,'8월'!$G$3:$H$11,2, false) -> 0 | I9: =VLOOKUP($B9,'9월'!$G$3:$H$11,2, false) -> 6 | J9: =VLOOKUP($B9,'10월'!$G$3:$H$11,2, false) -> 5 | K9: =VLOOKUP($B9,'11월'!$G$3:$H$11,2, false) -> 6 | L9: =VLOOKUP($B9,'12월'!$G$3:$H$11,2, false) -> 0 | M9: =VLOOKUP($B9,'2026-1월'!$G$3:$H$11,2, false) -> 0 | N9: =VLOOKUP($B9,'2026-2월'!$G$3:$H$11,2, false) -> 0 | O9: =sum(C9:N9) -> 36
B10: 금융 | C10: =VLOOKUP($B10,'3월'!$G$3:$H$11,2, false) -> 0 | D10: =VLOOKUP($B10,'4월'!$G$3:$H$11,2, false) -> 0 | E10: =VLOOKUP($B10,'5월'!$G$3:$H$11,2, false) -> 0 | F10: =VLOOKUP($B10,'6월'!$G$3:$H$11,2, false) -> 0 | G10: =VLOOKUP($B10,'7월'!$G$3:$H$11,2, false) -> 0 | H10: =VLOOKUP($B10,'8월'!$G$3:$H$11,2, false) -> 0 | I10: =VLOOKUP($B10,'9월'!$G$3:$H$11,2, false) -> 0 | J10: =VLOOKUP($B10,'10월'!$G$3:$H$11,2, false) -> 0 | K10: =VLOOKUP($B10,'11월'!$G$3:$H$11,2, false) -> 0 | L10: =VLOOKUP($B10,'12월'!$G$3:$H$11,2, false) -> 0 | M10: =VLOOKUP($B10,'2026-1월'!$G$3:$H$11,2, false) -> 0 | N10: =VLOOKUP($B10,'2026-2월'!$G$3:$H$11,2, false) -> 0 | O10: =sum(C10:N10) -> 0
B11: IT | C11: =VLOOKUP($B11,'3월'!$G$3:$H$11,2, false) -> 0 | D11: =VLOOKUP($B11,'4월'!$G$3:$H$11,2, false) -> 0 | E11: =VLOOKUP($B11,'5월'!$G$3:$H$11,2, false) -> 0 | F11: =VLOOKUP($B11,'6월'!$G$3:$H$11,2, false) -> 0 | G11: =VLOOKUP($B11,'7월'!$G$3:$H$11,2, false) -> 0 | H11: =VLOOKUP($B11,'8월'!$G$3:$H$11,2, false) -> 0 | I11: =VLOOKUP($B11,'9월'!$G$3:$H$11,2, false) -> 0 | J11: =VLOOKUP($B11,'10월'!$G$3:$H$11,2, false) -> 0 | K11: =VLOOKUP($B11,'11월'!$G$3:$H$11,2, false) -> 0 | L11: =VLOOKUP($B11,'12월'!$G$3:$H$11,2, false) -> 0 | M11: =VLOOKUP($B11,'2026-1월'!$G$3:$H$11,2, false) -> 0 | N11: =VLOOKUP($B11,'2026-2월'!$G$3:$H$11,2, false) -> 0 | O11: =sum(C11:N11) -> 0
B12: 임원면접 | C12: =VLOOKUP($B12,'3월'!$G$3:$H$11,2, false) -> 0 | D12: =VLOOKUP($B12,'4월'!$G$3:$H$11,2, false) -> 0 | E12: =VLOOKUP($B12,'5월'!$G$3:$H$11,2, false) -> 9 | F12: =VLOOKUP($B12,'6월'!$G$3:$H$11,2, false) -> 0 | G12: =VLOOKUP($B12,'7월'!$G$3:$H$11,2, false) -> 0 | H12: =VLOOKUP($B12,'8월'!$G$3:$H$11,2, false) -> 0 | I12: =VLOOKUP($B12,'9월'!$G$3:$H$11,2, false) -> 0 | J12: =VLOOKUP($B12,'10월'!$G$3:$H$11,2, false) -> 0 | K12: =VLOOKUP($B12,'11월'!$G$3:$H$11,2, false) -> 9 | L12: =VLOOKUP($B12,'12월'!$G$3:$H$11,2, false) -> 0 | M12: =VLOOKUP($B12,'2026-1월'!$G$3:$H$11,2, false) -> 0 | N12: =VLOOKUP($B12,'2026-2월'!$G$3:$H$11,2, false) -> 0 | O12: =sum(C12:N12) -> 18
B13: 합계 | C13: =sum(C3:C12) -> 209 | D13: =sum(D3:D12) -> 112 | E13: =sum(E3:E12) -> 145 | F13: =sum(F3:F12) -> 62 | G13: =sum(G3:G12) -> 54 | H13: =sum(H3:H12) -> 51 | I13: =sum(I3:I12) -> 192 | J13: =sum(J3:J12) -> 81 | ... N13: =sum(N3:N12) -> 30 | O13: =sum(C13:N13) -> 1248 | P13: =sum(O3:O12) -> 1248
B14: 컨설턴트별 | O14: 합계
B15: 강 진 | C15: =vlookup($B15,'3월'!$I:$J, 2, false) -> 25 | D15: =vlookup($B15,'4월'!$I:$J, 2, false) -> 6 | E15: =vlookup($B15,'5월'!$I:$J, 2, false) -> 11 | F15: =vlookup($B15,'6월'!$I:$J, 2, false) -> 6 | G15: =vlookup($B15,'7월'!$I:$J, 2, false) -> 4 | H15: =vlookup($B15,'8월'!$I:$J, 2, false) -> 4 | I15: =vlookup($B15,'9월'!$I:$J, 2, false) -> 10 | J15: =vlookup($B15,'10월'!$I:$J, 2, false) -> 3 | K15: =vlookup($B15,'11월'!$I:$J, 2, false) -> 11 | L15: =vlookup($B15,'12월'!$I:$J, 2, false) -> 4 | M15: =vlookup($B15,'2026-1월'!$I:$J, 2, false) -> 4 | N15: =vlookup($B15,'2026-2월'!$I:$J, 2, false) -> 4 | O15: =sum(C15:N15) -> 92
B16: 김나영 | C16: =vlookup($B16,'3월'!$I:$J, 2, false) -> 14 | D16: =vlookup($B16,'4월'!$I:$J, 2, false) -> 9 | E16: =vlookup($B16,'5월'!$I:$J, 2, false) -> 12 | F16: =vlookup($B16,'6월'!$I:$J, 2, false) -> 6 | G16: =vlookup($B16,'7월'!$I:$J, 2, false) -> 6 | H16: =vlookup($B16,'8월'!$I:$J, 2, false) -> 4 | I16: =vlookup($B16,'9월'!$I:$J, 2, false) -> 12 | J16: =vlookup($B16,'10월'!$I:$J, 2, false) -> 8 | K16: =vlookup($B16,'11월'!$I:$J, 2, false) -> 9 | L16: =vlookup($B16,'12월'!$I:$J, 2, false) -> 4 | M16: =vlookup($B16,'2026-1월'!$I:$J, 2, false) -> 8 | N16: =vlookup($B16,'2026-2월'!$I:$J, 2, false) -> 3 | O16: =sum(C16:N16) -> 95
B17: 김미령 | C17: =vlookup($B17,'3월'!$I:$J, 2, false) -> 0 | D17: =vlookup($B17,'4월'!$I:$J, 2, false) -> 0 | E17: =vlookup($B17,'5월'!$I:$J, 2, false) -> 0 | F17: =vlookup($B17,'6월'!$I:$J, 2, false) -> 0 | G17: =vlookup($B17,'7월'!$I:$J, 2, false) -> 0 | H17: =vlookup($B17,'8월'!$I:$J, 2, false) -> 0 | I17: =vlookup($B17,'9월'!$I:$J, 2, false) -> 0 | J17: =vlookup($B17,'10월'!$I:$J, 2, false) -> 0 | K17: =vlookup($B17,'11월'!$I:$J, 2, false) -> 0 | L17: =vlookup($B17,'12월'!$I:$J, 2, false) -> 0 | M17: =vlookup($B17,'2026-1월'!$I:$J, 2, false) -> 0 | N17: =vlookup($B17,'2026-2월'!$I:$J, 2, false) -> 0 | O17: =sum(C17:N17) -> 0
B18: 김민경 | C18: =vlookup($B18,'3월'!$I:$J, 2, false) -> 8 | D18: =vlookup($B18,'4월'!$I:$J, 2, false) -> 8 | E18: =vlookup($B18,'5월'!$I:$J, 2, false) -> 6 | F18: =vlookup($B18,'6월'!$I:$J, 2, false) -> 4 | G18: =vlookup($B18,'7월'!$I:$J, 2, false) -> 4 | H18: =vlookup($B18,'8월'!$I:$J, 2, false) -> 0 | I18: =vlookup($B18,'9월'!$I:$J, 2, false) -> 8 | J18: =vlookup($B18,'10월'!$I:$J, 2, false) -> 3 | K18: =vlookup($B18,'11월'!$I:$J, 2, false) -> 11 | L18: =vlookup($B18,'12월'!$I:$J, 2, false) -> 5 | M18: =vlookup($B18,'2026-1월'!$I:$J, 2, false) -> 2 | N18: =vlookup($B18,'2026-2월'!$I:$J, 2, false) -> 0 | O18: =sum(C18:N18) -> 59
B19: 김선화 | C19: =vlookup($B19,'3월'!$I:$J, 2, false) -> 10 | D19: =vlookup($B19,'4월'!$I:$J, 2, false) -> 6 | E19: =vlookup($B19,'5월'!$I:$J, 2, false) -> 8 | F19: =vlookup($B19,'6월'!$I:$J, 2, false) -> 4 | G19: =vlookup($B19,'7월'!$I:$J, 2, false) -> 4 | H19: =vlookup($B19,'8월'!$I:$J, 2, false) -> 6 | I19: =vlookup($B19,'9월'!$I:$J, 2, false) -> 8 | J19: =vlookup($B19,'10월'!$I:$J, 2, false) -> 6 | K19: =vlookup($B19,'11월'!$I:$J, 2, false) -> 8 | L19: =vlookup($B19,'12월'!$I:$J, 2, false) -> 4 | M19: =vlookup($B19,'2026-1월'!$I:$J, 2, false) -> 6 | N19: =vlookup($B19,'2026-2월'!$I:$J, 2, false) -> 3 | O19: =sum(C19:N19) -> 73
B20: 김세희 | C20: =vlookup($B20,'3월'!$I:$J, 2, false) -> 8 | D20: =vlookup($B20,'4월'!$I:$J, 2, false) -> 6 | E20: =vlookup($B20,'5월'!$I:$J, 2, false) -> 4 | F20: =vlookup($B20,'6월'!$I:$J, 2, false) -> 0 | G20: =vlookup($B20,'7월'!$I:$J, 2, false) -> 0 | H20: =vlookup($B20,'8월'!$I:$J, 2, false) -> 0 | I20: =vlookup($B20,'9월'!$I:$J, 2, false) -> 8 | J20: =vlookup($B20,'10월'!$I:$J, 2, false) -> 2 | K20: =vlookup($B20,'11월'!$I:$J, 2, false) -> 9 | L20: =vlookup($B20,'12월'!$I:$J, 2, false) -> 0 | M20: =vlookup($B20,'2026-1월'!$I:$J, 2, false) -> 0 | N20: =vlookup($B20,'2026-2월'!$I:$J, 2, false) -> 0 | O20: =sum(C20:N20) -> 37
B21: 김지현 | C21: =vlookup($B21,'3월'!$I:$J, 2, false) -> 11 | D21: =vlookup($B21,'4월'!$I:$J, 2, false) -> 6 | E21: =vlookup($B21,'5월'!$I:$J, 2, false) -> 7 | F21: =vlookup($B21,'6월'!$I:$J, 2, false) -> 4 | G21: =vlookup($B21,'7월'!$I:$J, 2, false) -> 6 | H21: =vlookup($B21,'8월'!$I:$J, 2, false) -> 4 | I21: =vlookup($B21,'9월'!$I:$J, 2, false) -> 14 | J21: =vlookup($B21,'10월'!$I:$J, 2, false) -> 5 | K21: =vlookup($B21,'11월'!$I:$J, 2, false) -> 11 | L21: =vlookup($B21,'12월'!$I:$J, 2, false) -> 5 | M21: =vlookup($B21,'2026-1월'!$I:$J, 2, false) -> 4 | N21: =vlookup($B21,'2026-2월'!$I:$J, 2, false) -> 0 | O21: =sum(C21:N21) -> 77
B22: 범하나 | C22: =vlookup($B22,'3월'!$I:$J, 2, false) -> 17 | D22: =vlookup($B22,'4월'!$I:$J, 2, false) -> 9 | E22: =vlookup($B22,'5월'!$I:$J, 2, false) -> 12 | F22: =vlookup($B22,'6월'!$I:$J, 2, false) -> 4 | G22: =vlookup($B22,'7월'!$I:$J, 2, false) -> 4 | H22: =vlookup($B22,'8월'!$I:$J, 2, false) -> 6 | I22: =vlookup($B22,'9월'!$I:$J, 2, false) -> 14 | J22: =vlookup($B22,'10월'!$I:$J, 2, false) -> 9 | K22: =vlookup($B22,'11월'!$I:$J, 2, false) -> 11 | L22: =vlookup($B22,'12월'!$I:$J, 2, false) -> 4 | M22: =vlookup($B22,'2026-1월'!$I:$J, 2, false) -> 5 | N22: =vlookup($B22,'2026-2월'!$I:$J, 2, false) -> 4 | O22: =sum(C22:N22) -> 99
B23: 성지우 | C23: =vlookup($B23,'3월'!$I:$J, 2, false) -> 5 | D23: =vlookup($B23,'4월'!$I:$J, 2, false) -> 2 | E23: =vlookup($B23,'5월'!$I:$J, 2, false) -> 4 | F23: =vlookup($B23,'6월'!$I:$J, 2, false) -> 2 | G23: =vlookup($B23,'7월'!$I:$J, 2, false) -> 0 | H23: =vlookup($B23,'8월'!$I:$J, 2, false) -> 0 | I23: =vlookup($B23,'9월'!$I:$J, 2, false) -> 4 | J23: =vlookup($B23,'10월'!$I:$J, 2, false) -> 2 | K23: =vlookup($B23,'11월'!$I:$J, 2, false) -> 5 | L23: =vlookup($B23,'12월'!$I:$J, 2, false) -> 3 | M23: =vlookup($B23,'2026-1월'!$I:$J, 2, false) -> 4 | N23: =vlookup($B23,'2026-2월'!$I:$J, 2, false) -> 2 | O23: =sum(C23:N23) -> 33
B24: 신민이 | C24: =vlookup($B24,'3월'!$I:$J, 2, false) -> 9 | D24: =vlookup($B24,'4월'!$I:$J, 2, false) -> 6 | E24: =vlookup($B24,'5월'!$I:$J, 2, false) -> 6 | F24: =vlookup($B24,'6월'!$I:$J, 2, false) -> 6 | G24: =vlookup($B24,'7월'!$I:$J, 2, false) -> 2 | H24: =vlookup($B24,'8월'!$I:$J, 2, false) -> 4 | I24: =vlookup($B24,'9월'!$I:$J, 2, false) -> 15 | J24: =vlookup($B24,'10월'!$I:$J, 2, false) -> 3 | K24: =vlookup($B24,'11월'!$I:$J, 2, false) -> 10 | L24: =vlookup($B24,'12월'!$I:$J, 2, false) -> 6 | M24: =vlookup($B24,'2026-1월'!$I:$J, 2, false) -> 5 | N24: =vlookup($B24,'2026-2월'!$I:$J, 2, false) -> 5 | O24: =sum(C24:N24) -> 77
B25: 심영섭 | C25: =vlookup($B25,'3월'!$I:$J, 2, false) -> 26 | D25: =vlookup($B25,'4월'!$I:$J, 2, false) -> 14 | E25: =vlookup($B25,'5월'!$I:$J, 2, false) -> 11 | F25: =vlookup($B25,'6월'!$I:$J, 2, false) -> 6 | G25: =vlookup($B25,'7월'!$I:$J, 2, false) -> 6 | H25: =vlookup($B25,'8월'!$I:$J, 2, false) -> 9 | I25: =vlookup($B25,'9월'!$I:$J, 2, false) -> 30 | J25: =vlookup($B25,'10월'!$I:$J, 2, false) -> 3 | K25: =vlookup($B25,'11월'!$I:$J, 2, false) -> 21 | L25: =vlookup($B25,'12월'!$I:$J, 2, false) -> 7 | M25: =vlookup($B25,'2026-1월'!$I:$J, 2, false) -> 8 | N25: =vlookup($B25,'2026-2월'!$I:$J, 2, false) -> 3 | O25: =sum(C25:N25) -> 144
B26: 양우석 | C26: =vlookup($B26,'3월'!$I:$J, 2, false) -> 0 | D26: =vlookup($B26,'4월'!$I:$J, 2, false) -> 0 | E26: =vlookup($B26,'5월'!$I:$J, 2, false) -> 10 | F26: =vlookup($B26,'6월'!$I:$J, 2, false) -> 0 | G26: =vlookup($B26,'7월'!$I:$J, 2, false) -> 0 | H26: =vlookup($B26,'8월'!$I:$J, 2, false) -> 0 | I26: =vlookup($B26,'9월'!$I:$J, 2, false) -> 0 | J26: =vlookup($B26,'10월'!$I:$J, 2, false) -> 0 | K26: =vlookup($B26,'11월'!$I:$J, 2, false) -> 9 | L26: =vlookup($B26,'12월'!$I:$J, 2, false) -> 0 | M26: =vlookup($B26,'2026-1월'!$I:$J, 2, false) -> 0 | N26: =vlookup($B26,'2026-2월'!$I:$J, 2, false) -> 0 | O26: =sum(C26:N26) -> 19
... B37: 민현정 | C37: =vlookup($B37,'3월'!$I:$J, 2, false) -> 0 | D37: =vlookup($B37,'4월'!$I:$J, 2, false) -> 0 | E37: =vlookup($B37,'5월'!$I:$J, 2, false) -> 0 | F37: =vlookup($B37,'6월'!$I:$J, 2, false) -> 0 | G37: =vlookup($B37,'7월'!$I:$J, 2, false) -> 0 | H37: =vlookup($B37,'8월'!$I:$J, 2, false) -> 0 | I37: =vlookup($B37,'9월'!$I:$J, 2, false) -> 0 | J37: =vlookup($B37,'10월'!$I:$J, 2, false) -> 0 | K37: =vlookup($B37,'11월'!$I:$J, 2, false) -> 0 | L37: =vlookup($B37,'12월'!$I:$J, 2, false) -> 0 | M37: =vlookup($B37,'2026-1월'!$I:$J, 2, false) -> 0 | N37: =vlookup($B37,'2026-2월'!$I:$J, 2, false) -> 0 | O37: =sum(C37:N37) -> 0
B38: 합계 | C38: =sum(C15:C37) -> 209 | D38: =sum(D15:D37) -> 112 | E38: =sum(E15:E37) -> 145 | F38: =sum(F15:F37) -> 62 | G38: =sum(G15:G37) -> 54 | H38: =sum(H15:H37) -> 51 | I38: =sum(I15:I37) -> 192 | J38: =sum(J15:J37) -> 81 | ... O38: =sum(O15:O37) -> 1248 | P38: =sum(O15:O37) -> 1248
