Workbook

Sheet 2025-상반기
A1: 컨설턴트명 | B1: 구분 | C1: 방식 | D1: 일자 | E1: 시간 | G1: 컨설턴트명 | H1: 진로취업 | I1: 서류면접 | J1: 공기업 | K1: 외국계 | L1: 이공계 | M1: 콘텐츠엔터 | N1: 임원면접 | O1: 합계 | Q1: 컨설턴트명 | R1: 03 | S1: 04 | T1: 05 | U1: 06 | V1: 07 | W1: 08 | X1: 합계
A2: 심영섭 | B2: 공기업 | C2: 대면 | D2: 45720 | E2: 0.45833333 | G2: 강 진 | H2: {=SUMPRODUCT(('2025-상반기'!$A:$A=$G2)*('2025-상반기'!$B:$B=H$1))} -> 0 | I2: {=SUMPRODUCT(('2025-상반기'!$A:$A=$G2)*('2025-상반기'!$B:$B=I$1))} -> 56 | J2: {=SUMPRODUCT(('2025-상반기'!$A:$A=$G2)*('2025-상반기'!$B:$B=J$1))} -> 0 | K2: {=SUMPRODUCT(('2025-상반기'!$A:$A=$G2)*('2025-상반기'!$B:$B=K$1))} -> 0 | L2: {=SUMPRODUCT(('2025-상반기'!$A:$A=$G2)*('2025-상반기'!$B:$B=L$1))} -> 0 | M2: {=SUMPRODUCT(('2025-상반기'!$A:$A=$G2)*('2025-상반기'!$B:$B=M$1))} -> 0 | N2: {=SUMPRODUCT(('2025-상반기'!$A:$A=$G2)*('2025-상반기'!$B:$B=N$1))} -> 0 | O2: =SUM(H2:N2) -> 56 | Q2: 강 진 | R2: 25 | S2: 6 | T2: 11 | U2: 6 | V2: 4 | W2: 4 | X2: =SUM(R2:W2) -> 56 | AA2: 일정변동 컨설팅
A3: 심영섭 | B3: 서류면접 | C3: 대면 | D3: 45720 | E3: 0.5 | G3: 김나영 | H3: {=SUMPRODUCT(('2025-상반기'!$A:$A=$G3)*('2025-상반기'!$B:$B=H$1))} -> 51 | I3: {=SUMPRODUCT(('2025-상반기'!$A:$A=$G3)*('2025-상반기'!$B:$B=I$1))} -> 0 | J3: {=SUMPRODUCT(('2025-상반기'!$A:$A=$G3)*('2025-상반기'!$B:$B=J$1))} -> 0 | K3: {=SUMPRODUCT(('2025-상반기'!$A:$A=$G3)*('2025-상반기'!$B:$B=K$1))} -> 0 | L3: {=SUMPRODUCT(('2025-상반기'!$A:$A=$G3)*('2025-상반기'!$B:$B=L$1))} -> 0 | M3: {=SUMPRODUCT(('2025-상반기'!$A:$A=$G3)*('2025-상반기'!$B:$B=M$1))} -> 0 | N3: {=SUMPRODUCT(('2025-상반기'!$A:$A=$G3)*('2025-상반기'!$B:$B=N$1))} -> 0 | O3: =SUM(H3:N3) -> 51 | Q3: 김나영 | R3: 14 | S3: 9 | T3: 12 | U3: 6 | V3: 6 | W3: 4 | X3: =SUM(R3:W3) -> 51 | Z3: 불참말고 취소 세션의 경우 더블체크요망
A4: 심영섭 | B4: 서류면접 | C4: 대면 | D4: 45720 | E4: 0.58333333 | G4: 김민경 | H4: {=SUMPRODUCT(('2025-상반기'!$A:$A=$G4)*('2025-상반기'!$B:$B=H$1))} -> 7 | I4: {=SUMPRODUCT(('2025-상반기'!$A:$A=$G4)*('2025-상반기'!$B:$B=I$1))} -> 23 | J4: {=SUMPRODUCT(('2025-상반기'!$A:$A=$G4)*('2025-상반기'!$B:$B=J$1))} -> 0 | K4: {=SUMPRODUCT(('2025-상반기'!$A:$A=$G4)*('2025-상반기'!$B:$B=K$1))} -> 0 | L4: {=SUMPRODUCT(('2025-상반기'!$A:$A=$G4)*('2025-상반기'!$B:$B=L$1))} -> 0 | M4: {=SUMPRODUCT(('2025-상반기'!$A:$A=$G4)*('2025-상반기'!$B:$B=M$1))} -> 0 | N4: {=SUMPRODUCT(('2025-상반기'!$A:$A=$G4)*('2025-상반기'!$B:$B=N$1))} -> 0 | O4: =SUM(H4:N4) -> 30 | Q4: 김민경 | R4: 8 | S4: 8 | T4: 6 | U4: 4 | V4: 4 | W4: 0 | X4: =SUM(R4:W4) -> 30
A5: 심영섭 | B5: 서류면접 | C5: 대면 | D5: 45720 | E5: 0.625 | G5: 김선화 | H5: {=SUMPRODUCT(('2025-상반기'!$A:$A=$G5)*('2025-상반기'!$B:$B=H$1))} -> 0 | I5: {=SUMPRODUCT(('2025-상반기'!$A:$A=$G5)*('2025-상반기'!$B:$B=I$1))} -> 32 | J5: {=SUMPRODUCT(('2025-상반기'!$A:$A=$G5)*('2025-상반기'!$B:$B=J$1))} -> 6 | K5: {=SUMPRODUCT(('2025-상반기'!$A:$A=$G5)*('2025-상반기'!$B:$B=K$1))} -> 0 | L5: {=SUMPRODUCT(('2025-상반기'!$A:$A=$G5)*('2025-상반기'!$B:$B=L$1))} -> 0 | M5: {=SUMPRODUCT(('2025-상반기'!$A:$A=$G5)*('2025-상반기'!$B:$B=M$1))} -> 0 | N5: {=SUMPRODUCT(('2025-상반기'!$A:$A=$G5)*('2025-상반기'!$B:$B=N$1))} -> 0 | O5: =SUM(H5:N5) -> 38 | Q5: 김선화 | R5: 10 | S5: 6 | T5: 8 | U5: 4 | V5: 4 | W5: 4 | X5: =SUM(R5:W5) -> 36
A6: 김민경 | B6: 서류면접 | C6: ZOOM | D6: 45721 | E6: 0.41666667 | G6: 김세희 | H6: {=SUMPRODUCT(('2025-상반기'!$A:$A=$G6)*('2025-상반기'!$B:$B=H$1))} -> 0 | I6: {=SUMPRODUCT(('2025-상반기'!$A:$A=$G6)*('2025-상반기'!$B:$B=I$1))} -> 1 | J6: {=SUMPRODUCT(('2025-상반기'!$A:$A=$G6)*('2025-상반기'!$B:$B=J$1))} -> 0 | K6: {=SUMPRODUCT(('2025-상반기'!$A:$A=$G6)*('2025-상반기'!$B:$B=K$1))} -> 0 | L6: {=SUMPRODUCT(('2025-상반기'!$A:$A=$G6)*('2025-상반기'!$B:$B=L$1))} -> 17 | M6: {=SUMPRODUCT(('2025-상반기'!$A:$A=$G6)*('2025-상반기'!$B:$B=M$1))} -> 0 | N6: {=SUMPRODUCT(('2025-상반기'!$A:$A=$G6)*('2025-상반기'!$B:$B=N$1))} -> 0 | O6: =SUM(H6:N6) -> 18 | Q6: 김세희 | R6: 8 | S6: 6 | T6: 4 | U6: 0 | V6: 0 | W6: 0 | X6: =SUM(R6:W6) -> 18
A7: 김민경 | B7: 서류면접 | C7: ZOOM | D7: 45721 | E7: 0.45833333 | G7: 김지현 | H7: {=SUMPRODUCT(('2025-상반기'!$A:$A=$G7)*('2025-상반기'!$B:$B=H$1))} -> 0 | I7: {=SUMPRODUCT(('2025-상반기'!$A:$A=$G7)*('2025-상반기'!$B:$B=I$1))} -> 38 | J7: {=SUMPRODUCT(('2025-상반기'!$A:$A=$G7)*('2025-상반기'!$B:$B=J$1))} -> 0 | K7: {=SUMPRODUCT(('2025-상반기'!$A:$A=$G7)*('2025-상반기'!$B:$B=K$1))} -> 0 | L7: {=SUMPRODUCT(('2025-상반기'!$A:$A=$G7)*('2025-상반기'!$B:$B=L$1))} -> 0 | M7: {=SUMPRODUCT(('2025-상반기'!$A:$A=$G7)*('2025-상반기'!$B:$B=M$1))} -> 0 | N7: {=SUMPRODUCT(('2025-상반기'!$A:$A=$G7)*('2025-상반기'!$B:$B=N$1))} -> 0 | O7: =SUM(H7:N7) -> 38 | Q7: 김지현 | R7: 11 | S7: 6 | T7: 7 | U7: 6 | V7: 4 | W7: 4 | X7: =SUM(R7:W7) -> 38
A8: 한 나 | B8: 서류면접 | C8: ZOOM | D8: 45721 | E8: 0.41666667 | G8: 범하나 | H8: {=SUMPRODUCT(('2025-상반기'!$A:$A=$G8)*('2025-상반기'!$B:$B=H$1))} -> 10 | I8: {=SUMPRODUCT(('2025-상반기'!$A:$A=$G8)*('2025-상반기'!$B:$B=I$1))} -> 42 | J8: {=SUMPRODUCT(('2025-상반기'!$A:$A=$G8)*('2025-상반기'!$B:$B=J$1))} -> 0 | K8: {=SUMPRODUCT(('2025-상반기'!$A:$A=$G8)*('2025-상반기'!$B:$B=K$1))} -> 0 | L8: {=SUMPRODUCT(('2025-상반기'!$A:$A=$G8)*('2025-상반기'!$B:$B=L$1))} -> 0 | M8: {=SUMPRODUCT(('2025-상반기'!$A:$A=$G8)*('2025-상반기'!$B:$B=M$1))} -> 0 | N8: {=SUMPRODUCT(('2025-상반기'!$A:$A=$G8)*('2025-상반기'!$B:$B=N$1))} -> 0 | O8: =SUM(H8:N8) -> 52 | Q8: 범하나 | R8: 17 | S8: 9 | T8: 12 | U8: 4 | V8: 4 | W8: 4 | X8: =SUM(R8:W8) -> 50
A9: 한 나 | B9: 서류면접 | C9: ZOOM | D9: 45721 | E9: 0.45833333 | G9: 성지우 | H9: {=SUMPRODUCT(('2025-상반기'!$A:$A=$G9)*('2025-상반기'!$B:$B=H$1))} -> 0 | I9: {=SUMPRODUCT(('2025-상반기'!$A:$A=$G9)*('2025-상반기'!$B:$B=I$1))} -> 0 | J9: {=SUMPRODUCT(('2025-상반기'!$A:$A=$G9)*('2025-상반기'!$B:$B=J$1))} -> 0 | K9: {=SUMPRODUCT(('2025-상반기'!$A:$A=$G9)*('2025-상반기'!$B:$B=K$1))} -> 13 | L9: {=SUMPRODUCT(('2025-상반기'!$A:$A=$G9)*('2025-상반기'!$B:$B=L$1))} -> 0 | M9: {=SUMPRODUCT(('2025-상반기'!$A:$A=$G9)*('2025-상반기'!$B:$B=M$1))} -> 0 | N9: {=SUMPRODUCT(('2025-상반기'!$A:$A=$G9)*('2025-상반기'!$B:$B=N$1))} -> 0 | O9: =SUM(H9:N9) -> 13 | Q9: 성지우 | R9: 5 | S9: 2 | T9: 4 | U9: 2 | V9: 0 | W9: 0 | X9: =SUM(R9:W9) -> 13
A10: 김선화 | B10: 공기업 | C10: ZOOM | D10: 45721 | E10: 0.4375 | G10: 신민이 | H10: {=SUMPRODUCT(('2025-상반기'!$A:$A=$G10)*('2025-상반기'!$B:$B=H$1))} -> 32 | I10: {=SUMPRODUCT(('2025-상반기'!$A:$A=$G10)*('2025-상반기'!$B:$B=I$1))} -> 1 | J10: {=SUMPRODUCT(('2025-상반기'!$A:$A=$G10)*('2025-상반기'!$B:$B=J$1))} -> 0 | K10: {=SUMPRODUCT(('2025-상반기'!$A:$A=$G10)*('2025-상반기'!$B:$B=K$1))} -> 0 | L10: {=SUMPRODUCT(('2025-상반기'!$A:$A=$G10)*('2025-상반기'!$B:$B=L$1))} -> 0 | M10: {=SUMPRODUCT(('2025-상반기'!$A:$A=$G10)*('2025-상반기'!$B:$B=M$1))} -> 0 | N10: {=SUMPRODUCT(('2025-상반기'!$A:$A=$G10)*('2025-상반기'!$B:$B=N$1))} -> 0 | O10: =SUM(H10:N10) -> 33 | Q10: 신민이 | R10: 9 | S10: 6 | T10: 6 | U10: 6 | V10: 2 | W10: 4 | X10: =SUM(R10:W10) -> 33
A11: 김선화 | B11: 서류면접 | C11: ZOOM | D11: 45721 | E11: 0.47916667 | G11: 심영섭 | H11: {=SUMPRODUCT(('2025-상반기'!$A:$A=$G11)*('2025-상반기'!$B:$B=H$1))} -> 1 | I11: {=SUMPRODUCT(('2025-상반기'!$A:$A=$G11)*('2025-상반기'!$B:$B=I$1))} -> 59 | J11: {=SUMPRODUCT(('2025-상반기'!$A:$A=$G11)*('2025-상반기'!$B:$B=J$1))} -> 12 | K11: {=SUMPRODUCT(('2025-상반기'!$A:$A=$G11)*('2025-상반기'!$B:$B=K$1))} -> 0 | L11: {=SUMPRODUCT(('2025-상반기'!$A:$A=$G11)*('2025-상반기'!$B:$B=L$1))} -> 0 | M11: {=SUMPRODUCT(('2025-상반기'!$A:$A=$G11)*('2025-상반기'!$B:$B=M$1))} -> 0 | N11: {=SUMPRODUCT(('2025-상반기'!$A:$A=$G11)*('2025-상반기'!$B:$B=N$1))} -> 0 | O11: =SUM(H11:N11) -> 72 | Q11: 심영섭 | R11: 26 | S11: 14 | T11: 11 | U11: 6 | V11: 6 | W11: 6 | X11: =SUM(R11:W11) -> 69
A12: 범하나 | B12: 서류면접 | C12: 대면 | D12: 45722 | E12: 0.4375 | G12: 양우석 | H12: {=SUMPRODUCT(('2025-상반기'!$A:$A=$G12)*('2025-상반기'!$B:$B=H$1))} -> 0 | I12: {=SUMPRODUCT(('2025-상반기'!$A:$A=$G12)*('2025-상반기'!$B:$B=I$1))} -> 1 | J12: {=SUMPRODUCT(('2025-상반기'!$A:$A=$G12)*('2025-상반기'!$B:$B=J$1))} -> 0 | K12: {=SUMPRODUCT(('2025-상반기'!$A:$A=$G12)*('2025-상반기'!$B:$B=K$1))} -> 0 | L12: {=SUMPRODUCT(('2025-상반기'!$A:$A=$G12)*('2025-상반기'!$B:$B=L$1))} -> 0 | M12: {=SUMPRODUCT(('2025-상반기'!$A:$A=$G12)*('2025-상반기'!$B:$B=M$1))} -> 0 | N12: {=SUMPRODUCT(('2025-상반기'!$A:$A=$G12)*('2025-상반기'!$B:$B=N$1))} -> 9 | O12: =SUM(H12:N12) -> 10 | Q12: 양우석 | R12: 0 | S12: 0 | T12: 10 | U12: 0 | V12: 0 | W12: 0 | X12: =SUM(R12:W12) -> 10
A13: 범하나 | B13: 서류면접 | C13: 대면 | D13: 45722 | E13: 0.47916667 | G13: 이상환 | H13: {=SUMPRODUCT(('2025-상반기'!$A:$A=$G13)*('2025-상반기'!$B:$B=H$1))} -> 0 | I13: {=SUMPRODUCT(('2025-상반기'!$A:$A=$G13)*('2025-상반기'!$B:$B=I$1))} -> 3 | J13: {=SUMPRODUCT(('2025-상반기'!$A:$A=$G13)*('2025-상반기'!$B:$B=J$1))} -> 0 | K13: {=SUMPRODUCT(('2025-상반기'!$A:$A=$G13)*('2025-상반기'!$B:$B=K$1))} -> 0 | L13: {=SUMPRODUCT(('2025-상반기'!$A:$A=$G13)*('2025-상반기'!$B:$B=L$1))} -> 0 | M13: {=SUMPRODUCT(('2025-상반기'!$A:$A=$G13)*('2025-상반기'!$B:$B=M$1))} -> 19 | N13: {=SUMPRODUCT(('2025-상반기'!$A:$A=$G13)*('2025-상반기'!$B:$B=N$1))} -> 0 | O13: =SUM(H13:N13) -> 22 | Q13: 이상환 | R13: 8 | S13: 6 | T13: 8 | U13: 0 | V13: 0 | W13: 0 | X13: =SUM(R13:W13) -> 22
A14: 범하나 | B14: 서류면접 | C14: 대면 | D14: 45722 | E14: 0.52083333 | G14: 이희영 | H14: {=SUMPRODUCT(('2025-상반기'!$A:$A=$G14)*('2025-상반기'!$B:$B=H$1))} -> 1 | I14: {=SUMPRODUCT(('2025-상반기'!$A:$A=$G14)*('2025-상반기'!$B:$B=I$1))} -> 50 | J14: {=SUMPRODUCT(('2025-상반기'!$A:$A=$G14)*('2025-상반기'!$B:$B=J$1))} -> 0 | K14: {=SUMPRODUCT(('2025-상반기'!$A:$A=$G14)*('2025-상반기'!$B:$B=K$1))} -> 0 | L14: {=SUMPRODUCT(('2025-상반기'!$A:$A=$G14)*('2025-상반기'!$B:$B=L$1))} -> 0 | M14: {=SUMPRODUCT(('2025-상반기'!$A:$A=$G14)*('2025-상반기'!$B:$B=M$1))} -> 0 | N14: {=SUMPRODUCT(('2025-상반기'!$A:$A=$G14)*('2025-상반기'!$B:$B=N$1))} -> 0 | O14: =SUM(H14:N14) -> 51 | Q14: 이희영 | R14: 21 | S14: 8 | T14: 12 | U14: 4 | V14: 4 | W14: 2 | X14: =SUM(R14:W14) -> 51
A15: 범하나 | B15: 서류면접 | C15: 대면 | D15: 45722 | E15: 0.5625 | G15: 장신혜 | H15: {=SUMPRODUCT(('2025-상반기'!$A:$A=$G15)*('2025-상반기'!$B:$B=H$1))} -> 0 | I15: {=SUMPRODUCT(('2025-상반기'!$A:$A=$G15)*('2025-상반기'!$B:$B=I$1))} -> 38 | J15: {=SUMPRODUCT(('2025-상반기'!$A:$A=$G15)*('2025-상반기'!$B:$B=J$1))} -> 0 | K15: {=SUMPRODUCT(('2025-상반기'!$A:$A=$G15)*('2025-상반기'!$B:$B=K$1))} -> 0 | L15: {=SUMPRODUCT(('2025-상반기'!$A:$A=$G15)*('2025-상반기'!$B:$B=L$1))} -> 0 | M15: {=SUMPRODUCT(('2025-상반기'!$A:$A=$G15)*('2025-상반기'!$B:$B=M$1))} -> 0 | N15: {=SUMPRODUCT(('2025-상반기'!$A:$A=$G15)*('2025-상반기'!$B:$B=N$1))} -> 0 | O15: =SUM(H15:N15) -> 38 | Q15: 장신혜 | R15: 12 | S15: 6 | T15: 10 | U15: 4 | V15: 4 | W15: 2 | X15: =SUM(R15:W15) -> 38
... A18: 김나영 | B18: 진로취업 | C18: ZOOM | D18: 45722 | E18: 0.45833333 | G18: 한 나 | H18: {=SUMPRODUCT(('2025-상반기'!$A:$A=$G18)*('2025-상반기'!$B:$B=H$1))} -> 11 | I18: {=SUMPRODUCT(('2025-상반기'!$A:$A=$G18)*('2025-상반기'!$B:$B=I$1))} -> 23 | J18: {=SUMPRODUCT(('2025-상반기'!$A:$A=$G18)*('2025-상반기'!$B:$B=J$1))} -> 0 | K18: {=SUMPRODUCT(('2025-상반기'!$A:$A=$G18)*('2025-상반기'!$B:$B=K$1))} -> 0 | L18: {=SUMPRODUCT(('2025-상반기'!$A:$A=$G18)*('2025-상반기'!$B:$B=L$1))} -> 0 | M18: {=SUMPRODUCT(('2025-상반기'!$A:$A=$G18)*('2025-상반기'!$B:$B=M$1))} -> 0 | N18: {=SUMPRODUCT(('2025-상반기'!$A:$A=$G18)*('2025-상반기'!$B:$B=N$1))} -> 0 | O18: =SUM(H18:N18) -> 34 | Q18: 한 나 | R18: 8 | S18: 6 | T18: 8 | U18: 4 | V18: 4 | W18: 4 | X18: =SUM(R18:W18) -> 34
A19: 김나영 | B19: 진로취업 | C19: ZOOM | D19: 45722 | E19: 0.5 | G19: 민현정 | H19: {=SUMPRODUCT(('2025-상반기'!$A:$A=$G19)*('2025-상반기'!$B:$B=H$1))} -> 0 | I19: {=SUMPRODUCT(('2025-상반기'!$A:$A=$G19)*('2025-상반기'!$B:$B=I$1))} -> 0 | J19: {=SUMPRODUCT(('2025-상반기'!$A:$A=$G19)*('2025-상반기'!$B:$B=J$1))} -> 0 | K19: {=SUMPRODUCT(('2025-상반기'!$A:$A=$G19)*('2025-상반기'!$B:$B=K$1))} -> 0 | L19: {=SUMPRODUCT(('2025-상반기'!$A:$A=$G19)*('2025-상반기'!$B:$B=L$1))} -> 0 | M19: {=SUMPRODUCT(('2025-상반기'!$A:$A=$G19)*('2025-상반기'!$B:$B=M$1))} -> 0 | N19: {=SUMPRODUCT(('2025-상반기'!$A:$A=$G19)*('2025-상반기'!$B:$B=N$1))} -> 0 | O19: =SUM(H19:N19) -> 0 | Q19: 민현정 | R19: - | S19: - | T19: - | U19: - | V19: - | W19: - | X19: =SUM(R19:W19) -> 0
A20: 김나영 | B20: 진로취업 | C20: ZOOM | D20: 45722 | E20: 0.54166667 | G20: 합계 | H20: =SUM(H2:H19) -> 113 | I20: =SUM(I2:I19) -> 371 | J20: =SUM(J2:J19) -> 18 | K20: =SUM(K2:K19) -> 34 | L20: =SUM(L2:L19) -> 67 | M20: =SUM(M2:M19) -> 19 | N20: =SUM(N2:N19) -> 9 | O20: =SUM(O2:O19) -> 631 | Q20: 합계 | R20: =SUM(R2:R19) -> 209 | S20: =SUM(S2:S19) -> 112 | T20: =SUM(T2:T19) -> 145 | U20: =SUM(U2:U19) -> 64 | V20: =SUM(V2:V19) -> 52 | W20: =SUM(W2:W19) -> 44 | X20: =SUM(X2:X19) -> 626
A21: 지명선 | B21: 외국계 | C21: ZOOM | D21: 45722 | E21: 0.41666667 | O21: =SUM(H20:N20) -> 631 | X21: =SUM(R20:W20) -> 626
A22: 지명선 | B22: 외국계 | C22: ZOOM | D22: 45722 | E22: 0.45833333
A23: 장신혜 | B23: 서류면접 | C23: ZOOM | D23: 45723 | E23: 0.41666667
A24: 장신혜 | B24: 서류면접 | C24: ZOOM | D24: 45723 | E24: 0.45833333
A25: 장신혜 | B25: 서류면접 | C25: ZOOM | D25: 45723 | E25: 0.5
A26: 이희영 | B26: 서류면접 | C26: ZOOM | D26: 45723 | E26: 0.39583333
A27: 이희영 | B27: 서류면접 | C27: ZOOM | D27: 45723 | E27: 0.4375
A28: 이희영 | B28: 서류면접 | C28: ZOOM | D28: 45723 | E28: 0.47916667
A29: 김세희 | B29: 이공계 | C29: ZOOM | D29: 45724 | E29: 0.375
A30: 김세희 | B30: 이공계 | C30: ZOOM | D30: 45724 | E30: 0.41666667
A31: 강 진 | B31: 서류면접 | C31: ZOOM | D31: 45724 | E31: 0.39583333
A32: 강 진 | B32: 서류면접 | C32: ZOOM | D32: 45724 | E32: 0.4375
A33: 심영섭 | B33: 서류면접 | C33: ZOOM | D33: 45724 | E33: 0.41666667
... A634: 범하나 | B634: 진로취업 | C634: ZOOM | D634: 45897 | E634: 0.47916667

Sheet 2025-하반기
G1: 변동된 이력 카운트 | Q1: 월별 당초 예정
A2: 컨설턴트명 | B2: 구분 | C2: 방식 | D2: 일자 | E2: 시간 | G2: 컨설턴트명 | H2: 진로개발 | I2: 서류면접 | J2: 공기업 | K2: 외국계 | L2: 이공계 | M2: 콘텐츠엔터 | N2: 임원면접 | O2: 합계 | Q2: 컨설턴트명 | R2: 09 | S2: 10 | T2: 11 | U2: 12 | V2: 01 | W2: 02 | X2: 합계
A3: 정지선 | B3: 이공계 | C3: 온라인 | D3: 45901 | E3: 0.41666667 | G3: 강 진 | H3: {=SUMPRODUCT(('2025-하반기'!$A:$A=$G3)*('2025-하반기'!$B:$B=H$2))} -> 0 | I3: {=SUMPRODUCT(('2025-하반기'!$A:$A=$G3)*('2025-하반기'!$B:$B=I$2))} -> 32 | J3: {=SUMPRODUCT(('2025-하반기'!$A:$A=$G3)*('2025-하반기'!$B:$B=J$2))} -> 0 | K3: {=SUMPRODUCT(('2025-하반기'!$A:$A=$G3)*('2025-하반기'!$B:$B=K$2))} -> 0 | L3: {=SUMPRODUCT(('2025-하반기'!$A:$A=$G3)*('2025-하반기'!$B:$B=L$2))} -> 0 | M3: {=SUMPRODUCT(('2025-하반기'!$A:$A=$G3)*('2025-하반기'!$B:$B=M$2))} -> 0 | N3: {=SUMPRODUCT(('2025-하반기'!$A:$A=$G3)*('2025-하반기'!$B:$B=N$2))} -> 0 | O3: =SUM(H3:N3) -> 32 | Q3: 강 진 | R3: 13 | S3: 3 | T3: 11 | U3: 4 | V3: 2 | W3: 2 | X3: =SUM(R3:W3) -> 35 | AA3: 일정변동 컨설팅
A4: 정지선 | B4: 이공계 | C4: 온라인 | D4: 45901 | E4: 0.45833333 | G4: 김나영 | H4: {=SUMPRODUCT(('2025-하반기'!$A:$A=$G4)*('2025-하반기'!$B:$B=H$2))} -> 38 | I4: {=SUMPRODUCT(('2025-하반기'!$A:$A=$G4)*('2025-하반기'!$B:$B=I$2))} -> 1 | J4: {=SUMPRODUCT(('2025-하반기'!$A:$A=$G4)*('2025-하반기'!$B:$B=J$2))} -> 0 | K4: {=SUMPRODUCT(('2025-하반기'!$A:$A=$G4)*('2025-하반기'!$B:$B=K$2))} -> 0 | L4: {=SUMPRODUCT(('2025-하반기'!$A:$A=$G4)*('2025-하반기'!$B:$B=L$2))} -> 0 | M4: {=SUMPRODUCT(('2025-하반기'!$A:$A=$G4)*('2025-하반기'!$B:$B=M$2))} -> 0 | N4: {=SUMPRODUCT(('2025-하반기'!$A:$A=$G4)*('2025-하반기'!$B:$B=N$2))} -> 0 | O4: =SUM(H4:N4) -> 39 | Q4: 김나영 | R4: 12 | S4: 8 | T4: 9 | U4: 4 | V4: 4 | W4: 2 | X4: =SUM(R4:W4) -> 39 | Z4: 불참말고 취소 세션의 경우 더블체크요망
A5: 정지선 | B5: 이공계 | C5: 온라인 | D5: 45901 | E5: 0.5 | G5: 김민경 | H5: {=SUMPRODUCT(('2025-하반기'!$A:$A=$G5)*('2025-하반기'!$B:$B=H$2))} -> 2 | I5: {=SUMPRODUCT(('2025-하반기'!$A:$A=$G5)*('2025-하반기'!$B:$B=I$2))} -> 27 | J5: {=SUMPRODUCT(('2025-하반기'!$A:$A=$G5)*('2025-하반기'!$B:$B=J$2))} -> 0 | K5: {=SUMPRODUCT(('2025-하반기'!$A:$A=$G5)*('2025-하반기'!$B:$B=K$2))} -> 0 | L5: {=SUMPRODUCT(('2025-하반기'!$A:$A=$G5)*('2025-하반기'!$B:$B=L$2))} -> 0 | M5: {=SUMPRODUCT(('2025-하반기'!$A:$A=$G5)*('2025-하반기'!$B:$B=M$2))} -> 0 | N5: {=SUMPRODUCT(('2025-하반기'!$A:$A=$G5)*('2025-하반기'!$B:$B=N$2))} -> 0 | O5: =SUM(H5:N5) -> 29 | Q5: 김민경 | R5: 9 | S5: 3 | T5: 11 | U5: 4 | V5: 2 | W5: 0 | X5: =SUM(R5:W5) -> 29
A6: 김지현 | B6: 서류면접 | C6: 대면 | D6: 45901 | E6: 0.4375 | G6: 김선화 | H6: {=SUMPRODUCT(('2025-하반기'!$A:$A=$G6)*('2025-하반기'!$B:$B=H$2))} -> 0 | I6: {=SUMPRODUCT(('2025-하반기'!$A:$A=$G6)*('2025-하반기'!$B:$B=I$2))} -> 18 | J6: {=SUMPRODUCT(('2025-하반기'!$A:$A=$G6)*('2025-하반기'!$B:$B=J$2))} -> 14 | K6: {=SUMPRODUCT(('2025-하반기'!$A:$A=$G6)*('2025-하반기'!$B:$B=K$2))} -> 0 | L6: {=SUMPRODUCT(('2025-하반기'!$A:$A=$G6)*('2025-하반기'!$B:$B=L$2))} -> 0 | M6: {=SUMPRODUCT(('2025-하반기'!$A:$A=$G6)*('2025-하반기'!$B:$B=M$2))} -> 0 | N6: {=SUMPRODUCT(('2025-하반기'!$A:$A=$G6)*('2025-하반기'!$B:$B=N$2))} -> 0 | O6: =SUM(H6:N6) -> 32 | Q6: 김선화 | R6: 8 | S6: 6 | T6: 8 | U6: 4 | V6: 4 | W6: 2 | X6: =SUM(R6:W6) -> 32
A7: 김지현(취소) | B7: 서류면접 | C7: 대면 | D7: 45901 | E7: 취소 | F7: 보충 11/14 | G7: 김세희 | H7: {=SUMPRODUCT(('2025-하반기'!$A:$A=$G7)*('2025-하반기'!$B:$B=H$2))} -> 0 | I7: {=SUMPRODUCT(('2025-하반기'!$A:$A=$G7)*('2025-하반기'!$B:$B=I$2))} -> 1 | J7: {=SUMPRODUCT(('2025-하반기'!$A:$A=$G7)*('2025-하반기'!$B:$B=J$2))} -> 0 | K7: {=SUMPRODUCT(('2025-하반기'!$A:$A=$G7)*('2025-하반기'!$B:$B=K$2))} -> 0 | L7: {=SUMPRODUCT(('2025-하반기'!$A:$A=$G7)*('2025-하반기'!$B:$B=L$2))} -> 18 | M7: {=SUMPRODUCT(('2025-하반기'!$A:$A=$G7)*('2025-하반기'!$B:$B=M$2))} -> 0 | N7: {=SUMPRODUCT(('2025-하반기'!$A:$A=$G7)*('2025-하반기'!$B:$B=N$2))} -> 0 | O7: =SUM(H7:N7) -> 19 | Q7: 김세희 | R7: 8 | S7: 2 | T7: 9 | U7: 0 | V7: 0 | W7: 0 | X7: =SUM(R7:W7) -> 19
A8: 김지현 | B8: 서류면접 | C8: 대면 | D8: 45901 | E8: 0.52083333 | G8: 김지현 | H8: {=SUMPRODUCT(('2025-하반기'!$A:$A=$G8)*('2025-하반기'!$B:$B=H$2))} -> 7 | I8: {=SUMPRODUCT(('2025-하반기'!$A:$A=$G8)*('2025-하반기'!$B:$B=I$2))} -> 32 | J8: {=SUMPRODUCT(('2025-하반기'!$A:$A=$G8)*('2025-하반기'!$B:$B=J$2))} -> 0 | K8: {=SUMPRODUCT(('2025-하반기'!$A:$A=$G8)*('2025-하반기'!$B:$B=K$2))} -> 0 | L8: {=SUMPRODUCT(('2025-하반기'!$A:$A=$G8)*('2025-하반기'!$B:$B=L$2))} -> 0 | M8: {=SUMPRODUCT(('2025-하반기'!$A:$A=$G8)*('2025-하반기'!$B:$B=M$2))} -> 0 | N8: {=SUMPRODUCT(('2025-하반기'!$A:$A=$G8)*('2025-하반기'!$B:$B=N$2))} -> 0 | O8: =SUM(H8:N8) -> 39 | Q8: 김지현 | R8: 16 | S8: 5 | T8: 11 | U8: 2 | V8: 4 | W8: 0 | X8: =SUM(R8:W8) -> 38
A9: 김지현 | B9: 서류면접 | C9: 대면 | D9: 45901 | E9: 0.58333333 | G9: 범하나 | H9: {=SUMPRODUCT(('2025-하반기'!$A:$A=$G9)*('2025-하반기'!$B:$B=H$2))} -> 13 | I9: {=SUMPRODUCT(('2025-하반기'!$A:$A=$G9)*('2025-하반기'!$B:$B=I$2))} -> 33 | J9: {=SUMPRODUCT(('2025-하반기'!$A:$A=$G9)*('2025-하반기'!$B:$B=J$2))} -> 0 | K9: {=SUMPRODUCT(('2025-하반기'!$A:$A=$G9)*('2025-하반기'!$B:$B=K$2))} -> 0 | L9: {=SUMPRODUCT(('2025-하반기'!$A:$A=$G9)*('2025-하반기'!$B:$B=L$2))} -> 0 | M9: {=SUMPRODUCT(('2025-하반기'!$A:$A=$G9)*('2025-하반기'!$B:$B=M$2))} -> 0 | N9: {=SUMPRODUCT(('2025-하반기'!$A:$A=$G9)*('2025-하반기'!$B:$B=N$2))} -> 0 | O9: =SUM(H9:N9) -> 46 | Q9: 범하나 | R9: 14 | S9: 9 | T9: 11 | U9: 4 | V9: 4 | W9: 4 | X9: =SUM(R9:W9) -> 46
A10: 김지현 | B10: 서류면접 | C10: 대면 | D10: 45901 | E10: 0.625
A11: 김지현 | B11: 서류면접 | C11: 온라인 | D11: 45901 | E11: 0.66666667
A12: 강 진 | B12: 서류면접 | C12: 대면 | D12: 45901 | E12: 0.54166667 | G12: 성지우 | H12: {=SUMPRODUCT(('2025-하반기'!$A:$A=$G12)*('2025-하반기'!$B:$B=H$2))} -> 0 | I12: {=SUMPRODUCT(('2025-하반기'!$A:$A=$G12)*('2025-하반기'!$B:$B=I$2))} -> 0 | J12: {=SUMPRODUCT(('2025-하반기'!$A:$A=$G12)*('2025-하반기'!$B:$B=J$2))} -> 0 | K12: {=SUMPRODUCT(('2025-하반기'!$A:$A=$G12)*('2025-하반기'!$B:$B=K$2))} -> 20 | L12: {=SUMPRODUCT(('2025-하반기'!$A:$A=$G12)*('2025-하반기'!$B:$B=L$2))} -> 0 | M12: {=SUMPRODUCT(('2025-하반기'!$A:$A=$G12)*('2025-하반기'!$B:$B=M$2))} -> 0 | N12: {=SUMPRODUCT(('2025-하반기'!$A:$A=$G12)*('2025-하반기'!$B:$B=N$2))} -> 0 | O12: =SUM(H12:N12) -> 20 | Q12: 성지우 | R12: 4 | S12: 2 | T12: 4 | U12: 2 | V12: 4 | W12: 2 | X12: =SUM(R12:W12) -> 18
A13: 강 진 | B13: 서류면접 | C13: 온라인 | D13: 45901 | E13: 0.58333333 | G13: 신민이 | H13: {=SUMPRODUCT(('2025-하반기'!$A:$A=$G13)*('2025-하반기'!$B:$B=H$2))} -> 36 | I13: {=SUMPRODUCT(('2025-하반기'!$A:$A=$G13)*('2025-하반기'!$B:$B=I$2))} -> 6 | J13: {=SUMPRODUCT(('2025-하반기'!$A:$A=$G13)*('2025-하반기'!$B:$B=J$2))} -> 0 | K13: {=SUMPRODUCT(('2025-하반기'!$A:$A=$G13)*('2025-하반기'!$B:$B=K$2))} -> 0 | L13: {=SUMPRODUCT(('2025-하반기'!$A:$A=$G13)*('2025-하반기'!$B:$B=L$2))} -> 0 | M13: {=SUMPRODUCT(('2025-하반기'!$A:$A=$G13)*('2025-하반기'!$B:$B=M$2))} -> 0 | N13: {=SUMPRODUCT(('2025-하반기'!$A:$A=$G13)*('2025-하반기'!$B:$B=N$2))} -> 0 | O13: =SUM(H13:N13) -> 42 | Q13: 신민이 | R13: 15 | S13: 3 | T13: 11 | U13: 6 | V13: 4 | W13: 4 | X13: =SUM(R13:W13) -> 43
A14: 강 진 | B14: 서류면접 | C14: 대면 | D14: 45901 | E14: 0.625 | G14: 심영섭 | H14: {=SUMPRODUCT(('2025-하반기'!$A:$A=$G14)*('2025-하반기'!$B:$B=H$2))} -> 0 | I14: {=SUMPRODUCT(('2025-하반기'!$A:$A=$G14)*('2025-하반기'!$B:$B=I$2))} -> 53 | J14: {=SUMPRODUCT(('2025-하반기'!$A:$A=$G14)*('2025-하반기'!$B:$B=J$2))} -> 14 | K14: {=SUMPRODUCT(('2025-하반기'!$A:$A=$G14)*('2025-하반기'!$B:$B=K$2))} -> 0 | L14: {=SUMPRODUCT(('2025-하반기'!$A:$A=$G14)*('2025-하반기'!$B:$B=L$2))} -> 0 | M14: {=SUMPRODUCT(('2025-하반기'!$A:$A=$G14)*('2025-하반기'!$B:$B=M$2))} -> 0 | N14: {=SUMPRODUCT(('2025-하반기'!$A:$A=$G14)*('2025-하반기'!$B:$B=N$2))} -> 0 | O14: =SUM(H14:N14) -> 67 | Q14: 심영섭 | R14: 27 | S14: 3 | T14: 20 | U14: 4 | V14: 4 | W14: 2 | X14: =SUM(R14:W14) -> 60
A15: 강 진 | B15: 서류면접 | C15: 온라인 | D15: 45901 | E15: 0.66666667 | G15: 양우석 | H15: {=SUMPRODUCT(('2025-하반기'!$A:$A=$G15)*('2025-하반기'!$B:$B=H$2))} -> 0 | I15: {=SUMPRODUCT(('2025-하반기'!$A:$A=$G15)*('2025-하반기'!$B:$B=I$2))} -> 0 | J15: {=SUMPRODUCT(('2025-하반기'!$A:$A=$G15)*('2025-하반기'!$B:$B=J$2))} -> 0 | K15: {=SUMPRODUCT(('2025-하반기'!$A:$A=$G15)*('2025-하반기'!$B:$B=K$2))} -> 0 | L15: {=SUMPRODUCT(('2025-하반기'!$A:$A=$G15)*('2025-하반기'!$B:$B=L$2))} -> 0 | M15: {=SUMPRODUCT(('2025-하반기'!$A:$A=$G15)*('2025-하반기'!$B:$B=M$2))} -> 0 | N15: {=SUMPRODUCT(('2025-하반기'!$A:$A=$G15)*('2025-하반기'!$B:$B=N$2))} -> 9 | O15: =SUM(H15:N15) -> 9 | Q15: 양우석 | R15: 0 | S15: 0 | T15: 9 | U15: 0 | V15: 0 | W15: 0 | X15: =SUM(R15:W15) -> 9
A16: 신민이 | B16: 서류면접 | C16: 온라인 | D16: 45902 | E16: 0.41666667 | G16: 이상환 | H16: {=SUMPRODUCT(('2025-하반기'!$A:$A=$G16)*('2025-하반기'!$B:$B=H$2))} -> 0 | I16: {=SUMPRODUCT(('2025-하반기'!$A:$A=$G16)*('2025-하반기'!$B:$B=I$2))} -> 3 | J16: {=SUMPRODUCT(('2025-하반기'!$A:$A=$G16)*('2025-하반기'!$B:$B=J$2))} -> 0 | K16: {=SUMPRODUCT(('2025-하반기'!$A:$A=$G16)*('2025-하반기'!$B:$B=K$2))} -> 0 | L16: {=SUMPRODUCT(('2025-하반기'!$A:$A=$G16)*('2025-하반기'!$B:$B=L$2))} -> 0 | M16: {=SUMPRODUCT(('2025-하반기'!$A:$A=$G16)*('2025-하반기'!$B:$B=M$2))} -> 17 | N16: {=SUMPRODUCT(('2025-하반기'!$A:$A=$G16)*('2025-하반기'!$B:$B=N$2))} -> 0 | O16: =SUM(H16:N16) -> 20 | Q16: 이상환 | R16: 8 | S16: 6 | T16: 6 | U16: 0 | V16: 0 | W16: 0 | X16: =SUM(R16:W16) -> 20
A17: 신민이 | B17: 서류면접 | C17: 온라인 | D17: 45902 | E17: 0.45833333 | G17: 이희영 | H17: {=SUMPRODUCT(('2025-하반기'!$A:$A=$G17)*('2025-하반기'!$B:$B=H$2))} -> 0 | I17: {=SUMPRODUCT(('2025-하반기'!$A:$A=$G17)*('2025-하반기'!$B:$B=I$2))} -> 66 | J17: {=SUMPRODUCT(('2025-하반기'!$A:$A=$G17)*('2025-하반기'!$B:$B=J$2))} -> 0 | K17: {=SUMPRODUCT(('2025-하반기'!$A:$A=$G17)*('2025-하반기'!$B:$B=K$2))} -> 0 | L17: {=SUMPRODUCT(('2025-하반기'!$A:$A=$G17)*('2025-하반기'!$B:$B=L$2))} -> 0 | M17: {=SUMPRODUCT(('2025-하반기'!$A:$A=$G17)*('2025-하반기'!$B:$B=M$2))} -> 0 | N17: {=SUMPRODUCT(('2025-하반기'!$A:$A=$G17)*('2025-하반기'!$B:$B=N$2))} -> 0 | O17: =SUM(H17:N17) -> 66 | Q17: 이희영 | R17: 21 | S17: 12 | T17: 20 | U17: 6 | V17: 4 | W17: 0 | X17: =SUM(R17:W17) -> 63
A18: 신민이 | B18: 서류면접 | C18: 온라인 | D18: 45902 | E18: 0.5 | G18: 장신혜 | H18: {=SUMPRODUCT(('2025-하반기'!$A:$A=$G18)*('2025-하반기'!$B:$B=H$2))} -> 0 | I18: {=SUMPRODUCT(('2025-하반기'!$A:$A=$G18)*('2025-하반기'!$B:$B=I$2))} -> 43 | J18: {=SUMPRODUCT(('2025-하반기'!$A:$A=$G18)*('2025-하반기'!$B:$B=J$2))} -> 0 | K18: {=SUMPRODUCT(('2025-하반기'!$A:$A=$G18)*('2025-하반기'!$B:$B=K$2))} -> 0 | L18: {=SUMPRODUCT(('2025-하반기'!$A:$A=$G18)*('2025-하반기'!$B:$B=L$2))} -> 0 | M18: {=SUMPRODUCT(('2025-하반기'!$A:$A=$G18)*('2025-하반기'!$B:$B=M$2))} -> 0 | N18: {=SUMPRODUCT(('2025-하반기'!$A:$A=$G18)*('2025-하반기'!$B:$B=N$2))} -> 0 | O18: =SUM(H18:N18) -> 43 | Q18: 장신혜 | R18: 9 | S18: 12 | T18: 11 | U18: 6 | V18: 4 | W18: 2 | X18: =SUM(R18:W18) -> 44
A19: 심영섭 | B19: 공기업 | C19: 대면 | D19: 45902 | E19: 0.41666667 | G19: 정지선 | H19: {=SUMPRODUCT(('2025-하반기'!$A:$A=$G19)*('2025-하반기'!$B:$B=H$2))} -> 2 | I19: {=SUMPRODUCT(('2025-하반기'!$A:$A=$G19)*('2025-하반기'!$B:$B=I$2))} -> 4 | J19: {=SUMPRODUCT(('2025-하반기'!$A:$A=$G19)*('2025-하반기'!$B:$B=J$2))} -> 0 | K19: {=SUMPRODUCT(('2025-하반기'!$A:$A=$G19)*('2025-하반기'!$B:$B=K$2))} -> 0 | L19: {=SUMPRODUCT(('2025-하반기'!$A:$A=$G19)*('2025-하반기'!$B:$B=L$2))} -> 32 | M19: {=SUMPRODUCT(('2025-하반기'!$A:$A=$G19)*('2025-하반기'!$B:$B=M$2))} -> 0 | N19: {=SUMPRODUCT(('2025-하반기'!$A:$A=$G19)*('2025-하반기'!$B:$B=N$2))} -> 0 | O19: =SUM(H19:N19) -> 38 | Q19: 정지선 | R19: 15 | S19: 3 | T19: 11 | U19: 4 | V19: 2 | W19: 2 | X19: =SUM(R19:W19) -> 37
A20: 심영섭 | B20: 서류면접 | C20: 대면 | D20: 45902 | E20: 0.45833333 | G20: 지명선 | H20: {=SUMPRODUCT(('2025-하반기'!$A:$A=$G20)*('2025-하반기'!$B:$B=H$2))} -> 0 | I20: {=SUMPRODUCT(('2025-하반기'!$A:$A=$G20)*('2025-하반기'!$B:$B=I$2))} -> 0 | J20: {=SUMPRODUCT(('2025-하반기'!$A:$A=$G20)*('2025-하반기'!$B:$B=J$2))} -> 0 | K20: {=SUMPRODUCT(('2025-하반기'!$A:$A=$G20)*('2025-하반기'!$B:$B=K$2))} -> 14 | L20: {=SUMPRODUCT(('2025-하반기'!$A:$A=$G20)*('2025-하반기'!$B:$B=L$2))} -> 0 | M20: {=SUMPRODUCT(('2025-하반기'!$A:$A=$G20)*('2025-하반기'!$B:$B=M$2))} -> 0 | N20: {=SUMPRODUCT(('2025-하반기'!$A:$A=$G20)*('2025-하반기'!$B:$B=N$2))} -> 0 | O20: =SUM(H20:N20) -> 14 | Q20: 지명선 | R20: 4 | S20: 2 | T20: 4 | U20: 2 | V20: 4 | W20: 0 | X20: =SUM(R20:W20) -> 16
A21: 심영섭 | B21: 서류면접 | C21: 대면 | D21: 45902 | E21: 0.5 | G21: 한 나 | H21: {=SUMPRODUCT(('2025-하반기'!$A:$A=$G21)*('2025-하반기'!$B:$B=H$2))} -> 6 | I21: {=SUMPRODUCT(('2025-하반기'!$A:$A=$G21)*('2025-하반기'!$B:$B=I$2))} -> 26 | J21: {=SUMPRODUCT(('2025-하반기'!$A:$A=$G21)*('2025-하반기'!$B:$B=J$2))} -> 0 | K21: {=SUMPRODUCT(('2025-하반기'!$A:$A=$G21)*('2025-하반기'!$B:$B=K$2))} -> 0 | L21: {=SUMPRODUCT(('2025-하반기'!$A:$A=$G21)*('2025-하반기'!$B:$B=L$2))} -> 0 | M21: {=SUMPRODUCT(('2025-하반기'!$A:$A=$G21)*('2025-하반기'!$B:$B=M$2))} -> 0 | N21: {=SUMPRODUCT(('2025-하반기'!$A:$A=$G21)*('2025-하반기'!$B:$B=N$2))} -> 0 | O21: =SUM(H21:N21) -> 32 | Q21: 한 나 | R21: 10 | S21: 6 | T21: 8 | U21: 4 | V21: 4 | W21: 2 | X21: =SUM(R21:W21) -> 34
A22: 심영섭 | B22: 서류면접 | C22: 대면 | D22: 45902 | E22: 0.58333333
A23: 심영섭 | B23: 서류면접 | C23: 대면 | D23: 45902 | E23: 0.625
A24: 심영섭 | B24: 서류면접 | C24: 대면 | D24: 45902 | E24: 0.66666667
A25: 이희영 | B25: 서류면접 | C25: 온라인 | D25: 45902 | E25: 0.47916667 | G25: 민현정 | H25: {=SUMPRODUCT(('2025-하반기'!$A:$A=$G25)*('2025-하반기'!$B:$B=H$2))} -> 0 | I25: {=SUMPRODUCT(('2025-하반기'!$A:$A=$G25)*('2025-하반기'!$B:$B=I$2))} -> 0 | J25: {=SUMPRODUCT(('2025-하반기'!$A:$A=$G25)*('2025-하반기'!$B:$B=J$2))} -> 0 | K25: {=SUMPRODUCT(('2025-하반기'!$A:$A=$G25)*('2025-하반기'!$B:$B=K$2))} -> 0 | L25: {=SUMPRODUCT(('2025-하반기'!$A:$A=$G25)*('2025-하반기'!$B:$B=L$2))} -> 0 | M25: {=SUMPRODUCT(('2025-하반기'!$A:$A=$G25)*('2025-하반기'!$B:$B=M$2))} -> 0 | N25: {=SUMPRODUCT(('2025-하반기'!$A:$A=$G25)*('2025-하반기'!$B:$B=N$2))} -> 0 | O25: =SUM(H25:N25) -> 0 | Q25: 민현정 | R25: - | S25: - | T25: - | U25: - | V25: - | W25: - | X25: =SUM(R25:W25) -> 0
A26: 이희영 | B26: 서류면접 | C26: 온라인 | D26: 45902 | E26: 0.52083333 | G26: 합계 | H26: =SUM(H3:H25) -> 104 | I26: =SUM(I3:I25) -> 345 | J26: =SUM(J3:J25) -> 28 | K26: =SUM(K3:K25) -> 34 | L26: =SUM(L3:L25) -> 50 | M26: =SUM(M3:M25) -> 17 | N26: =SUM(N3:N25) -> 9 | O26: =SUM(O3:O25) -> 587 | Q26: 합계 | R26: =SUM(R3:R25) -> 193 | S26: =SUM(S3:S25) -> 85 | T26: =SUM(T3:T25) -> 174 | U26: =SUM(U3:U25) -> 56 | V26: =SUM(V3:V25) -> 50 | W26: =SUM(W3:W25) -> 24 | X26: =SUM(X3:X25) -> 582
A27: 이희영 | B27: 서류면접 | C27: 온라인 | D27: 45902 | E27: 0.5625 | N27: =SUM(I26:N26) -> 483 | O27: =SUM(H26:N26) -> 587 | X27: =SUM(R26:W26) -> 582
A28: 한 나 | B28: 서류면접 | C28: 온라인 | D28: 45903 | E28: 0.41666667
A29: 한 나 | B29: 서류면접 | C29: 온라인 | D29: 45903 | E29: 0.45833333
A30: 한 나 | B30: 서류면접 | C30: 온라인 | D30: 45903 | E30: 0.5
A31: 범하나 | B31: 서류면접 | C31: 대면 | D31: 45903 | E31: 0.45833333 | G31: (참고)당초 | H31: 104 | I31: 328 | J31: 31 | K31: 34 | L31: 56 | M31: 20 | N31: 9 | O31: =SUM(H31:N31) -> 582
A32: 범하나 | B32: 서류면접 | C32: 대면 | D32: 45903 | E32: 0.5 | N32: =SUM(I31:N31) -> 478
A33: 범하나 | B33: 서류면접 | C33: 대면 | D33: 45903 | E33: 0.54166667
A34: 범하나 | B34: 서류면접 | C34: 대면 | D34: 45903 | E34: 0.58333333
A35: 성지우 | B35: 외국계 | C35: 온라인 | D35: 45903 | E35: 0.625
A36: 성지우 | B36: 외국계 | C36: 온라인 | D36: 45903 | E36: 0.66666667
A37: 김선화 | B37: 공기업 | D37: 45904 | E37: 0.41666667
A38: 김선화 | B38: 서류면접 | D38: 45904 | E38: 0.45833333
A39: 이상환 | B39: 콘텐츠엔터 | D39: 45904 | E39: 0.4375
A40: 이상환 | B40: 콘텐츠엔터 | D40: 45904 | E40: 0.47916667
...
